Workbook

Sheet 日常水質
A1: 加計浄化センター維持管理週報 | M1: 令和8年度
O3: 平均
A4: 全日電力量 | G4: Kｗｈ
A5: 力測電力量 | G5: Kｗｈ
A6: 無効電力量 | G6: Kvar
A7: デマンド | G7: Kw
A8: 水道使用量 | G8: ㎥
A9: 軽油(残量) | G9: ℓ
A10: 返送汚泥流量 | G10: ㎥
A11: 余剰汚泥流量 | G11: ㎥
A12: 放流流量 | G12: ㎥
A13: 日 常 水 質 測 定 結 果
A14: 測 定 項 目 | I14: 測定日 | O14: =O3
I15: 測定者
A16: 水温 | G16: ℃ | I16: 流入
I17: ディッチ
I18: 放流
A19: 外観 | C19: 油膜・色合 | I19: 流入
I20: ディッチ
I21: 放流
A22: 透視度 | G22: ｃｍ | I22: 流入水
I23: 放流水
A24: 臭気 | C24: 腐敗臭 | G24: 有無 | I24: 流入
I25: ディッチ
I26: 放流
A27: PH | G27: ― | I27: 流入
I28: ディッチ
I29: 放流
A30: SV | C30: SV・10 | G30: ％ | I30: ディッチ
C31: SV・20
C32: SV・30
C33: SV・24h
A34: MLSS | G34: ㎎/ℓ | I34: ディッチ
A35: 汚泥界面 | G35: ｃｍ | I35: 終沈
A36: 残留塩素 | G36: ㎎/ℓ | I36: 放流水
A37: 塩素投入量 | G37: kg | I37: 塩素混和池
A38: 備 考
A47: 加計浄化センター維持管理週報
O49: 平均
A50: 全日電力量 | G50: Kｗｈ
...

Sheet 日常機械設備
A1: 機械設備日常点検表（１/２） | K1: 令和8年3月分
A2: 機 器 名 | B2: No | C2: 点 検 者
C3: 点検内容
A4: ポンプ井 | B4: ― | C4: 内部状況確認
A5: 汚水ポンプ | B5: 1 | C5: 電流値 | D5: Ａ
C6: 吐出圧力 | D6: Mpa
C7: 異音、振動
B8: 2 | C8: 電流値 | D8: Ａ
C9: 吐出圧力 | D9: Mpa
C10: =C7
B11: ― | C11: モード確認
C12: 常用機選択
A13: スクリーンユニット | C13: 異音、振動
C14: し渣量の確認
C15: 運転動作
A16: エアレーション装置 | B16: 1-1 | C16: 電流値 | D16: Ａ
C17: =C13
C18: =C11
B19: 1-2 | C19: 電流値 | D19: Ａ
C20: =C17
C21: =C18
A22: 曝気ブロワー | B22: №１ | C22: 電流値 | D22: Ａ
C23: =C20
C24: =C21
B25: №２ | C25: 電流値 | D25: Ａ
C26: =C23
C27: =C24
A28: 消泡装置 | B28: ― | C28: 消泡ノズル
C29: 消泡状態
A30: ディッチ流出可動堰 | B30: 1 | C30: 開度 | D30: ㎜
A31: ディッチ流出ゲート | B31: 1 | C31: 開度 | D31: ㎜
A32: ディッチ連絡ゲート | B32: － | C32: 開度 | D32: ㎜
A33: 終沈汚泥掻寄機 | B33: 1 | C33: 電流値 | D33: Ａ
C34: 異音、振動等
A35: スカムスキマー | B35: 1 | C35: 動作状況
C36: スカムの状況
A37: 返送汚泥ポンプ | B37: 1-1 | C37: 電流値 | D37: Ａ
C38: 吐出圧力 | D38: Mpa
C39: 異音、振動
B40: 1-2 | C40: 電流値 | D40: Ａ
...

Sheet 日常電気設備
A1: 電気設備日常点検（１/２） | K1: =日常機械設備!K1
A3: 電 気 室 | B3: 引込・受電 | C3: 電圧 | F3: KV
F4: モード | X4: =K4-J4
C5: 力率 | F5: ψ
C6: 電流 | F6: A
F7: モード
C8: 普通電力量（×１０ｋw） | F8: 読み
F9: 使用量
C10: 引込・受電設定 | F10: 手動/自動
F11: 切/入
B12: 変圧器 | C12: 主変圧器温度 | F12: ℃
C13: 異音、脱臭の有無 | F13: 有・無
B14: 低 圧 分 岐 | C14: 動力（２１０V） 電圧 | F14: V
F15: モード
C16: 動力（２１０V） 電流 | F16: A
F17: モード
C18: 照明(210-105V) 電流 | F18: A
F19: モード
C20: 低圧分岐設備 | F20: 買電/自家発
C21: 動力制御盤1 | F21: 読み
C22: （×１ｋｗｈ） | F22: 使用量
C23: 動力制御盤2 | F23: 読み
C24: （×１ｋｗｈ） | F24: 使用量
C25: 動力制御盤3 | F25: 読み
C26: （×１ｋｗｈ） | F26: 使用量
C27: 動力制御盤4 | F27: 読み
C28: （×１ｋｗｈ） | F28: 使用量
C29: No.１ コンデンサー(電磁接触器) | F29: 切/入
C30: No.２ コンデンサー(電磁接触器) | F30: 切/入
C31: No.３ コンデンサー(電磁接触器) | F31: 切/入
A32: 備 考
A35: 電気設備日常点検（２/２）
B36: 機器名 | D36: 点 検 者 氏 名
D37: 点 検 内 容
A38: 計 装 設 備 | B38: ポンプ井 水位計 | D38: 外観の確認
D39: 指示状況の確認
D40: 計器読み | F40: ｍ
B41: Nｏ．１オキシデーションディッチＤＯ計 | D41: 外観の確認
D42: 指示状況の確認
D43: ＤＯ値 | F43: ㎎/ℓ
...

Sheet 運転管理月報
A1: 加計浄化センター運転管理月報 | J1: =水質管理報告!O1
A2: 日付 | B2: 曜日 | C2: 全日電力量読み値 | D2: 力測電力量読み値 | E2: 無効電力量読み値 | F2: 上水使用量読み値 | G2: 固形塩素 | H2: 脱水ケーキ | J2: No.1 | L2: 余剰汚泥 流量 | N2: 放流流量
G3: 使用量 | H3: 発生量 | I3: 搬出量 | J3: 返送汚泥
J4: 流 量
C5: kwh | D5: kwh | E5: kvarh | F5: ㎥ | G5: kg | H5: ｔ | I5: ｔ | J5: ㎥ | L5: ㎥ | N5: ㎥
A6: =IFERROR(IF(AND(ISNUMBER(日常水質!$P$1),YEAR(日常水質!$P$1)>=2000),DATE(YEAR(日常水質!$P$1),MONTH(日常水質!$P$1),1),NA()),IFERROR(IF(AND(ISNUMBER(日常水質!$I$95),YEAR(日常水質!$I$95)>=2000),DATE(YEAR(日常水質!$I$95),MONTH(日常水質!$I$95),1),NA()),IFERROR(IF(AND(ISNUMBER(日常水質!$I$49),YEAR(日常水質!$I$49)>=2000),DATE(YEAR(日常水質!$I$49),MONTH(日常水質!$I$49),1),NA()),IFERROR(IF(AND(ISNUMBER(日常水質!$I$141),YEAR(日常水質!$I$141)>=2000),DATE(YEAR(日常水質!$I$141),MONTH(日常水質!$I$141),1),NA()),IFERROR(IF(AND(ISNUMBER(日常水質!$I$187),YEAR(日常水質!$I$187)>=2000),DATE(YEAR(日常水質!$I$187),MONTH(日常水質!$I$187),1),NA()),IFERROR(IF(AND(ISNUMBER(日常水質!$I$3),YEAR(日常水質!$I$3)>=2000),DATE(YEAR(日常水質!$I$3),MONTH(日常水質!$I$3),1),NA()),"")))))) | B6: =IF(ISNUMBER(A6),A6,"")
A7: =IF(ISNUMBER(A6),IF(MONTH(A6+1)=MONTH($A$6),A6+1,""),"") | B7: =IF(ISNUMBER(A7),A7,"") | C7: =IFERROR(IFERROR(IFERROR(IFERROR(IFERROR(INDEX(日常水質!$I$4:$N$4,MATCH($A7,日常水質!$I$3:$N$3,0)),INDEX(日常水質!$I$50:$N$50,MATCH($A7,日常水質!$I$49:$N$49,0))),INDEX(日常水質!$I$96:$N$96,MATCH($A7,日常水質!$I$95:$N$95,0))),INDEX(日常水質!$I$142:$N$142,MATCH($A7,日常水質!$I$141:$N$141,0))),INDEX(日常水質!$I$188:$N$188,MATCH($A7,日常水質!$I$187:$N$187,0))),"") | D7: =IFERROR(IFERROR(IFERROR(IFERROR(IFERROR(INDEX(日常水質!$I$5:$N$5,MATCH($A7,日常水質!$I$3:$N$3,0)),INDEX(日常水質!$I$51:$N$51,MATCH($A7,日常水質!$I$49:$N$49,0))),INDEX(日常水質!$I$97:$N$97,MATCH($A7,日常水質!$I$95:$N$95,0))),INDEX(日常水質!$I$143:$N$143,MATCH($A7,日常水質!$I$141:$N$141,0))),INDEX(日常水質!$I$189:$N$189,MATCH($A7,日常水質!$I$187:$N$187,0))),"") | E7: =IFERROR(IFERROR(IFERROR(IFERROR(IFERROR(INDEX(日常水質!$I$6:$N$6,MATCH($A7,日常水質!$I$3:$N$3,0)),INDEX(日常水質!$I$52:$N$52,MATCH($A7,日常水質!$I$49:$N$49,0))),INDEX(日常水質!$I$98:$N$98,MATCH($A7,日常水質!$I$95:$N$95,0))),INDEX(日常水質!$I$144:$N$144,MATCH($A7,日常水質!$I$141:$N$141,0))),INDEX(日常水質!$I$190:$N$190,MATCH($A7,日常水質!$I$187:$N$187,0))),"") | F7: =IFERROR(IFERROR(IFERROR(IFERROR(IFERROR(INDEX(日常水質!$I$8:$N$8,MATCH($A7,日常水質!$I$3:$N$3,0)),INDEX(日常水質!$I$54:$N$54,MATCH($A7,日常水質!$I$49:$N$49,0))),INDEX(日常水質!$I$100:$N$100,MATCH($A7,日常水質!$I$95:$N$95,0))),INDEX(日常水質!$I$146:$N$146,MATCH($A7,日常水質!$I$141:$N$141,0))),INDEX(日常水質!$I$192:$N$192,MATCH($A7,日常水質!$I$187:$N$187,0))),"") | J7: =IFERROR(IFERROR(IFERROR(IFERROR(IFERROR(INDEX(日常水質!$I$10:$N$10,MATCH($A7,日常水質!$I$3:$N$3,0)),INDEX(日常水質!$I$56:$N$56,MATCH($A7,日常水質!$I$49:$N$49,0))),INDEX(日常水質!$I$102:$N$102,MATCH($A7,日常水質!$I$95:$N$95,0))),INDEX(日常水質!$I$148:$N$148,MATCH($A7,日常水質!$I$141:$N$141,0))),INDEX(日常水質!$I$194:$N$194,MATCH($A7,日常水質!$I$187:$N$187,0))),"") | K7: =IF(J7="","",IFERROR((J7-LOOKUP(2,1/(J$6:J6<>""),J$6:J6))/(A7-LOOKUP(2,1/(J$6:J6<>""),A$6:A6)),"")) | L7: =IFERROR(IFERROR(IFERROR(IFERROR(IFERROR(INDEX(日常水質!$I$11:$N$11,MATCH($A7,日常水質!$I$3:$N$3,0)),INDEX(日常水質!$I$57:$N$57,MATCH($A7,日常水質!$I$49:$N$49,0))),INDEX(日常水質!$I$103:$N$103,MATCH($A7,日常水質!$I$95:$N$95,0))),INDEX(日常水質!$I$149:$N$149,MATCH($A7,日常水質!$I$141:$N$141,0))),INDEX(日常水質!$I$195:$N$195,MATCH($A7,日常水質!$I$187:$N$187,0))),"") | M7: =IF(L7="","",IFERROR((L7-LOOKUP(2,1/(L$6:L6<>""),L$6:L6))/(A7-LOOKUP(2,1/(L$6:L6<>""),A$6:A6)),"")) | N7: =IFERROR(IFERROR(IFERROR(IFERROR(IFERROR(INDEX(日常水質!$I$12:$N$12,MATCH($A7,日常水質!$I$3:$N$3,0)),INDEX(日常水質!$I$58:$N$58,MATCH($A7,日常水質!$I$49:$N$49,0))),INDEX(日常水質!$I$104:$N$104,MATCH($A7,日常水質!$I$95:$N$95,0))),INDEX(日常水質!$I$150:$N$150,MATCH($A7,日常水質!$I$141:$N$141,0))),INDEX(日常水質!$I$196:$N$196,MATCH($A7,日常水質!$I$187:$N$187,0))),"")
A8: =IF(ISNUMBER(A7),IF(MONTH(A7+1)=MONTH($A$6),A7+1,""),"") | B8: =IF(ISNUMBER(A8),A8,"") | C8: =IFERROR(IFERROR(IFERROR(IFERROR(IFERROR(INDEX(日常水質!$I$4:$N$4,MATCH($A8,日常水質!$I$3:$N$3,0)),INDEX(日常水質!$I$50:$N$50,MATCH($A8,日常水質!$I$49:$N$49,0))),INDEX(日常水質!$I$96:$N$96,MATCH($A8,日常水質!$I$95:$N$95,0))),INDEX(日常水質!$I$142:$N$142,MATCH($A8,日常水質!$I$141:$N$141,0))),INDEX(日常水質!$I$188:$N$188,MATCH($A8,日常水質!$I$187:$N$187,0))),"") | D8: =IFERROR(IFERROR(IFERROR(IFERROR(IFERROR(INDEX(日常水質!$I$5:$N$5,MATCH($A8,日常水質!$I$3:$N$3,0)),INDEX(日常水質!$I$51:$N$51,MATCH($A8,日常水質!$I$49:$N$49,0))),INDEX(日常水質!$I$97:$N$97,MATCH($A8,日常水質!$I$95:$N$95,0))),INDEX(日常水質!$I$143:$N$143,MATCH($A8,日常水質!$I$141:$N$141,0))),INDEX(日常水質!$I$189:$N$189,MATCH($A8,日常水質!$I$187:$N$187,0))),"") | E8: =IFERROR(IFERROR(IFERROR(IFERROR(IFERROR(INDEX(日常水質!$I$6:$N$6,MATCH($A8,日常水質!$I$3:$N$3,0)),INDEX(日常水質!$I$52:$N$52,MATCH($A8,日常水質!$I$49:$N$49,0))),INDEX(日常水質!$I$98:$N$98,MATCH($A8,日常水質!$I$95:$N$95,0))),INDEX(日常水質!$I$144:$N$144,MATCH($A8,日常水質!$I$141:$N$141,0))),INDEX(日常水質!$I$190:$N$190,MATCH($A8,日常水質!$I$187:$N$187,0))),"") | F8: =IFERROR(IFERROR(IFERROR(IFERROR(IFERROR(INDEX(日常水質!$I$8:$N$8,MATCH($A8,日常水質!$I$3:$N$3,0)),INDEX(日常水質!$I$54:$N$54,MATCH($A8,日常水質!$I$49:$N$49,0))),INDEX(日常水質!$I$100:$N$100,MATCH($A8,日常水質!$I$95:$N$95,0))),INDEX(日常水質!$I$146:$N$146,MATCH($A8,日常水質!$I$141:$N$141,0))),INDEX(日常水質!$I$192:$N$192,MATCH($A8,日常水質!$I$187:$N$187,0))),"") | J8: =IFERROR(IFERROR(IFERROR(IFERROR(IFERROR(INDEX(日常水質!$I$10:$N$10,MATCH($A8,日常水質!$I$3:$N$3,0)),INDEX(日常水質!$I$56:$N$56,MATCH($A8,日常水質!$I$49:$N$49,0))),INDEX(日常水質!$I$102:$N$102,MATCH($A8,日常水質!$I$95:$N$95,0))),INDEX(日常水質!$I$148:$N$148,MATCH($A8,日常水質!$I$141:$N$141,0))),INDEX(日常水質!$I$194:$N$194,MATCH($A8,日常水質!$I$187:$N$187,0))),"") | K8: =IF(J8="","",IFERROR((J8-LOOKUP(2,1/(J$6:J7<>""),J$6:J7))/(A8-LOOKUP(2,1/(J$6:J7<>""),A$6:A7)),"")) | L8: =IFERROR(IFERROR(IFERROR(IFERROR(IFERROR(INDEX(日常水質!$I$11:$N$11,MATCH($A8,日常水質!$I$3:$N$3,0)),INDEX(日常水質!$I$57:$N$57,MATCH($A8,日常水質!$I$49:$N$49,0))),INDEX(日常水質!$I$103:$N$103,MATCH($A8,日常水質!$I$95:$N$95,0))),INDEX(日常水質!$I$149:$N$149,MATCH($A8,日常水質!$I$141:$N$141,0))),INDEX(日常水質!$I$195:$N$195,MATCH($A8,日常水質!$I$187:$N$187,0))),"") | M8: =IF(L8="","",IFERROR((L8-LOOKUP(2,1/(L$6:L7<>""),L$6:L7))/(A8-LOOKUP(2,1/(L$6:L7<>""),A$6:A7)),"")) | N8: =IFERROR(IFERROR(IFERROR(IFERROR(IFERROR(INDEX(日常水質!$I$12:$N$12,MATCH($A8,日常水質!$I$3:$N$3,0)),INDEX(日常水質!$I$58:$N$58,MATCH($A8,日常水質!$I$49:$N$49,0))),INDEX(日常水質!$I$104:$N$104,MATCH($A8,日常水質!$I$95:$N$95,0))),INDEX(日常水質!$I$150:$N$150,MATCH($A8,日常水質!$I$141:$N$141,0))),INDEX(日常水質!$I$196:$N$196,MATCH($A8,日常水質!$I$187:$N$187,0))),"")
A9: =IF(ISNUMBER(A8),IF(MONTH(A8+1)=MONTH($A$6),A8+1,""),"") | B9: =IF(ISNUMBER(A9),A9,"") | C9: =IFERROR(IFERROR(IFERROR(IFERROR(IFERROR(INDEX(日常水質!$I$4:$N$4,MATCH($A9,日常水質!$I$3:$N$3,0)),INDEX(日常水質!$I$50:$N$50,MATCH($A9,日常水質!$I$49:$N$49,0))),INDEX(日常水質!$I$96:$N$96,MATCH($A9,日常水質!$I$95:$N$95,0))),INDEX(日常水質!$I$142:$N$142,MATCH($A9,日常水質!$I$141:$N$141,0))),INDEX(日常水質!$I$188:$N$188,MATCH($A9,日常水質!$I$187:$N$187,0))),"") | D9: =IFERROR(IFERROR(IFERROR(IFERROR(IFERROR(INDEX(日常水質!$I$5:$N$5,MATCH($A9,日常水質!$I$3:$N$3,0)),INDEX(日常水質!$I$51:$N$51,MATCH($A9,日常水質!$I$49:$N$49,0))),INDEX(日常水質!$I$97:$N$97,MATCH($A9,日常水質!$I$95:$N$95,0))),INDEX(日常水質!$I$143:$N$143,MATCH($A9,日常水質!$I$141:$N$141,0))),INDEX(日常水質!$I$189:$N$189,MATCH($A9,日常水質!$I$187:$N$187,0))),"") | E9: =IFERROR(IFERROR(IFERROR(IFERROR(IFERROR(INDEX(日常水質!$I$6:$N$6,MATCH($A9,日常水質!$I$3:$N$3,0)),INDEX(日常水質!$I$52:$N$52,MATCH($A9,日常水質!$I$49:$N$49,0))),INDEX(日常水質!$I$98:$N$98,MATCH($A9,日常水質!$I$95:$N$95,0))),INDEX(日常水質!$I$144:$N$144,MATCH($A9,日常水質!$I$141:$N$141,0))),INDEX(日常水質!$I$190:$N$190,MATCH($A9,日常水質!$I$187:$N$187,0))),"") | F9: =IFERROR(IFERROR(IFERROR(IFERROR(IFERROR(INDEX(日常水質!$I$8:$N$8,MATCH($A9,日常水質!$I$3:$N$3,0)),INDEX(日常水質!$I$54:$N$54,MATCH($A9,日常水質!$I$49:$N$49,0))),INDEX(日常水質!$I$100:$N$100,MATCH($A9,日常水質!$I$95:$N$95,0))),INDEX(日常水質!$I$146:$N$146,MATCH($A9,日常水質!$I$141:$N$141,0))),INDEX(日常水質!$I$192:$N$192,MATCH($A9,日常水質!$I$187:$N$187,0))),"") | J9: =IFERROR(IFERROR(IFERROR(IFERROR(IFERROR(INDEX(日常水質!$I$10:$N$10,MATCH($A9,日常水質!$I$3:$N$3,0)),INDEX(日常水質!$I$56:$N$56,MATCH($A9,日常水質!$I$49:$N$49,0))),INDEX(日常水質!$I$102:$N$102,MATCH($A9,日常水質!$I$95:$N$95,0))),INDEX(日常水質!$I$148:$N$148,MATCH($A9,日常水質!$I$141:$N$141,0))),INDEX(日常水質!$I$194:$N$194,MATCH($A9,日常水質!$I$187:$N$187,0))),"") | K9: =IF(J9="","",IFERROR((J9-LOOKUP(2,1/(J$6:J8<>""),J$6:J8))/(A9-LOOKUP(2,1/(J$6:J8<>""),A$6:A8)),"")) | L9: =IFERROR(IFERROR(IFERROR(IFERROR(IFERROR(INDEX(日常水質!$I$11:$N$11,MATCH($A9,日常水質!$I$3:$N$3,0)),INDEX(日常水質!$I$57:$N$57,MATCH($A9,日常水質!$I$49:$N$49,0))),INDEX(日常水質!$I$103:$N$103,MATCH($A9,日常水質!$I$95:$N$95,0))),INDEX(日常水質!$I$149:$N$149,MATCH($A9,日常水質!$I$141:$N$141,0))),INDEX(日常水質!$I$195:$N$195,MATCH($A9,日常水質!$I$187:$N$187,0))),"") | M9: =IF(L9="","",IFERROR((L9-LOOKUP(2,1/(L$6:L8<>""),L$6:L8))/(A9-LOOKUP(2,1/(L$6:L8<>""),A$6:A8)),"")) | N9: =IFERROR(IFERROR(IFERROR(IFERROR(IFERROR(INDEX(日常水質!$I$12:$N$12,MATCH($A9,日常水質!$I$3:$N$3,0)),INDEX(日常水質!$I$58:$N$58,MATCH($A9,日常水質!$I$49:$N$49,0))),INDEX(日常水質!$I$104:$N$104,MATCH($A9,日常水質!$I$95:$N$95,0))),INDEX(日常水質!$I$150:$N$150,MATCH($A9,日常水質!$I$141:$N$141,0))),INDEX(日常水質!$I$196:$N$196,MATCH($A9,日常水質!$I$187:$N$187,0))),"")
A10: =IF(ISNUMBER(A9),IF(MONTH(A9+1)=MONTH($A$6),A9+1,""),"") | B10: =IF(ISNUMBER(A10),A10,"") | C10: =IFERROR(IFERROR(IFERROR(IFERROR(IFERROR(INDEX(日常水質!$I$4:$N$4,MATCH($A10,日常水質!$I$3:$N$3,0)),INDEX(日常水質!$I$50:$N$50,MATCH($A10,日常水質!$I$49:$N$49,0))),INDEX(日常水質!$I$96:$N$96,MATCH($A10,日常水質!$I$95:$N$95,0))),INDEX(日常水質!$I$142:$N$142,MATCH($A10,日常水質!$I$141:$N$141,0))),INDEX(日常水質!$I$188:$N$188,MATCH($A10,日常水質!$I$187:$N$187,0))),"") | D10: =IFERROR(IFERROR(IFERROR(IFERROR(IFERROR(INDEX(日常水質!$I$5:$N$5,MATCH($A10,日常水質!$I$3:$N$3,0)),INDEX(日常水質!$I$51:$N$51,MATCH($A10,日常水質!$I$49:$N$49,0))),INDEX(日常水質!$I$97:$N$97,MATCH($A10,日常水質!$I$95:$N$95,0))),INDEX(日常水質!$I$143:$N$143,MATCH($A10,日常水質!$I$141:$N$141,0))),INDEX(日常水質!$I$189:$N$189,MATCH($A10,日常水質!$I$187:$N$187,0))),"") | E10: =IFERROR(IFERROR(IFERROR(IFERROR(IFERROR(INDEX(日常水質!$I$6:$N$6,MATCH($A10,日常水質!$I$3:$N$3,0)),INDEX(日常水質!$I$52:$N$52,MATCH($A10,日常水質!$I$49:$N$49,0))),INDEX(日常水質!$I$98:$N$98,MATCH($A10,日常水質!$I$95:$N$95,0))),INDEX(日常水質!$I$144:$N$144,MATCH($A10,日常水質!$I$141:$N$141,0))),INDEX(日常水質!$I$190:$N$190,MATCH($A10,日常水質!$I$187:$N$187,0))),"") | F10: =IFERROR(IFERROR(IFERROR(IFERROR(IFERROR(INDEX(日常水質!$I$8:$N$8,MATCH($A10,日常水質!$I$3:$N$3,0)),INDEX(日常水質!$I$54:$N$54,MATCH($A10,日常水質!$I$49:$N$49,0))),INDEX(日常水質!$I$100:$N$100,MATCH($A10,日常水質!$I$95:$N$95,0))),INDEX(日常水質!$I$146:$N$146,MATCH($A10,日常水質!$I$141:$N$141,0))),INDEX(日常水質!$I$192:$N$192,MATCH($A10,日常水質!$I$187:$N$187,0))),"") | J10: =IFERROR(IFERROR(IFERROR(IFERROR(IFERROR(INDEX(日常水質!$I$10:$N$10,MATCH($A10,日常水質!$I$3:$N$3,0)),INDEX(日常水質!$I$56:$N$56,MATCH($A10,日常水質!$I$49:$N$49,0))),INDEX(日常水質!$I$102:$N$102,MATCH($A10,日常水質!$I$95:$N$95,0))),INDEX(日常水質!$I$148:$N$148,MATCH($A10,日常水質!$I$141:$N$141,0))),INDEX(日常水質!$I$194:$N$194,MATCH($A10,日常水質!$I$187:$N$187,0))),"") | K10: =IF(J10="","",IFERROR((J10-LOOKUP(2,1/(J$6:J9<>""),J$6:J9))/(A10-LOOKUP(2,1/(J$6:J9<>""),A$6:A9)),"")) | L10: =IFERROR(IFERROR(IFERROR(IFERROR(IFERROR(INDEX(日常水質!$I$11:$N$11,MATCH($A10,日常水質!$I$3:$N$3,0)),INDEX(日常水質!$I$57:$N$57,MATCH($A10,日常水質!$I$49:$N$49,0))),INDEX(日常水質!$I$103:$N$103,MATCH($A10,日常水質!$I$95:$N$95,0))),INDEX(日常水質!$I$149:$N$149,MATCH($A10,日常水質!$I$141:$N$141,0))),INDEX(日常水質!$I$195:$N$195,MATCH($A10,日常水質!$I$187:$N$187,0))),"") | M10: =IF(L10="","",IFERROR((L10-LOOKUP(2,1/(L$6:L9<>""),L$6:L9))/(A10-LOOKUP(2,1/(L$6:L9<>""),A$6:A9)),"")) | N10: =IFERROR(IFERROR(IFERROR(IFERROR(IFERROR(INDEX(日常水質!$I$12:$N$12,MATCH($A10,日常水質!$I$3:$N$3,0)),INDEX(日常水質!$I$58:$N$58,MATCH($A10,日常水質!$I$49:$N$49,0))),INDEX(日常水質!$I$104:$N$104,MATCH($A10,日常水質!$I$95:$N$95,0))),INDEX(日常水質!$I$150:$N$150,MATCH($A10,日常水質!$I$141:$N$141,0))),INDEX(日常水質!$I$196:$N$196,MATCH($A10,日常水質!$I$187:$N$187,0))),"")
A11: =IF(ISNUMBER(A10),IF(MONTH(A10+1)=MONTH($A$6),A10+1,""),"") | B11: =IF(ISNUMBER(A11),A11,"") | C11: =IFERROR(IFERROR(IFERROR(IFERROR(IFERROR(INDEX(日常水質!$I$4:$N$4,MATCH($A11,日常水質!$I$3:$N$3,0)),INDEX(日常水質!$I$50:$N$50,MATCH($A11,日常水質!$I$49:$N$49,0))),INDEX(日常水質!$I$96:$N$96,MATCH($A11,日常水質!$I$95:$N$95,0))),INDEX(日常水質!$I$142:$N$142,MATCH($A11,日常水質!$I$141:$N$141,0))),INDEX(日常水質!$I$188:$N$188,MATCH($A11,日常水質!$I$187:$N$187,0))),"") | D11: =IFERROR(IFERROR(IFERROR(IFERROR(IFERROR(INDEX(日常水質!$I$5:$N$5,MATCH($A11,日常水質!$I$3:$N$3,0)),INDEX(日常水質!$I$51:$N$51,MATCH($A11,日常水質!$I$49:$N$49,0))),INDEX(日常水質!$I$97:$N$97,MATCH($A11,日常水質!$I$95:$N$95,0))),INDEX(日常水質!$I$143:$N$143,MATCH($A11,日常水質!$I$141:$N$141,0))),INDEX(日常水質!$I$189:$N$189,MATCH($A11,日常水質!$I$187:$N$187,0))),"") | E11: =IFERROR(IFERROR(IFERROR(IFERROR(IFERROR(INDEX(日常水質!$I$6:$N$6,MATCH($A11,日常水質!$I$3:$N$3,0)),INDEX(日常水質!$I$52:$N$52,MATCH($A11,日常水質!$I$49:$N$49,0))),INDEX(日常水質!$I$98:$N$98,MATCH($A11,日常水質!$I$95:$N$95,0))),INDEX(日常水質!$I$144:$N$144,MATCH($A11,日常水質!$I$141:$N$141,0))),INDEX(日常水質!$I$190:$N$190,MATCH($A11,日常水質!$I$187:$N$187,0))),"") | F11: =IFERROR(IFERROR(IFERROR(IFERROR(IFERROR(INDEX(日常水質!$I$8:$N$8,MATCH($A11,日常水質!$I$3:$N$3,0)),INDEX(日常水質!$I$54:$N$54,MATCH($A11,日常水質!$I$49:$N$49,0))),INDEX(日常水質!$I$100:$N$100,MATCH($A11,日常水質!$I$95:$N$95,0))),INDEX(日常水質!$I$146:$N$146,MATCH($A11,日常水質!$I$141:$N$141,0))),INDEX(日常水質!$I$192:$N$192,MATCH($A11,日常水質!$I$187:$N$187,0))),"") | J11: =IFERROR(IFERROR(IFERROR(IFERROR(IFERROR(INDEX(日常水質!$I$10:$N$10,MATCH($A11,日常水質!$I$3:$N$3,0)),INDEX(日常水質!$I$56:$N$56,MATCH($A11,日常水質!$I$49:$N$49,0))),INDEX(日常水質!$I$102:$N$102,MATCH($A11,日常水質!$I$95:$N$95,0))),INDEX(日常水質!$I$148:$N$148,MATCH($A11,日常水質!$I$141:$N$141,0))),INDEX(日常水質!$I$194:$N$194,MATCH($A11,日常水質!$I$187:$N$187,0))),"") | K11: =IF(J11="","",IFERROR((J11-LOOKUP(2,1/(J$6:J10<>""),J$6:J10))/(A11-LOOKUP(2,1/(J$6:J10<>""),A$6:A10)),"")) | L11: =IFERROR(IFERROR(IFERROR(IFERROR(IFERROR(INDEX(日常水質!$I$11:$N$11,MATCH($A11,日常水質!$I$3:$N$3,0)),INDEX(日常水質!$I$57:$N$57,MATCH($A11,日常水質!$I$49:$N$49,0))),INDEX(日常水質!$I$103:$N$103,MATCH($A11,日常水質!$I$95:$N$95,0))),INDEX(日常水質!$I$149:$N$149,MATCH($A11,日常水質!$I$141:$N$141,0))),INDEX(日常水質!$I$195:$N$195,MATCH($A11,日常水質!$I$187:$N$187,0))),"") | M11: =IF(L11="","",IFERROR((L11-LOOKUP(2,1/(L$6:L10<>""),L$6:L10))/(A11-LOOKUP(2,1/(L$6:L10<>""),A$6:A10)),"")) | N11: =IFERROR(IFERROR(IFERROR(IFERROR(IFERROR(INDEX(日常水質!$I$12:$N$12,MATCH($A11,日常水質!$I$3:$N$3,0)),INDEX(日常水質!$I$58:$N$58,MATCH($A11,日常水質!$I$49:$N$49,0))),INDEX(日常水質!$I$104:$N$104,MATCH($A11,日常水質!$I$95:$N$95,0))),INDEX(日常水質!$I$150:$N$150,MATCH($A11,日常水質!$I$141:$N$141,0))),INDEX(日常水質!$I$196:$N$196,MATCH($A11,日常水質!$I$187:$N$187,0))),"")
A12: =IF(ISNUMBER(A11),IF(MONTH(A11+1)=MONTH($A$6),A11+1,""),"") | B12: =IF(ISNUMBER(A12),A12,"") | C12: =IFERROR(IFERROR(IFERROR(IFERROR(IFERROR(INDEX(日常水質!$I$4:$N$4,MATCH($A12,日常水質!$I$3:$N$3,0)),INDEX(日常水質!$I$50:$N$50,MATCH($A12,日常水質!$I$49:$N$49,0))),INDEX(日常水質!$I$96:$N$96,MATCH($A12,日常水質!$I$95:$N$95,0))),INDEX(日常水質!$I$142:$N$142,MATCH($A12,日常水質!$I$141:$N$141,0))),INDEX(日常水質!$I$188:$N$188,MATCH($A12,日常水質!$I$187:$N$187,0))),"") | D12: =IFERROR(IFERROR(IFERROR(IFERROR(IFERROR(INDEX(日常水質!$I$5:$N$5,MATCH($A12,日常水質!$I$3:$N$3,0)),INDEX(日常水質!$I$51:$N$51,MATCH($A12,日常水質!$I$49:$N$49,0))),INDEX(日常水質!$I$97:$N$97,MATCH($A12,日常水質!$I$95:$N$95,0))),INDEX(日常水質!$I$143:$N$143,MATCH($A12,日常水質!$I$141:$N$141,0))),INDEX(日常水質!$I$189:$N$189,MATCH($A12,日常水質!$I$187:$N$187,0))),"") | E12: =IFERROR(IFERROR(IFERROR(IFERROR(IFERROR(INDEX(日常水質!$I$6:$N$6,MATCH($A12,日常水質!$I$3:$N$3,0)),INDEX(日常水質!$I$52:$N$52,MATCH($A12,日常水質!$I$49:$N$49,0))),INDEX(日常水質!$I$98:$N$98,MATCH($A12,日常水質!$I$95:$N$95,0))),INDEX(日常水質!$I$144:$N$144,MATCH($A12,日常水質!$I$141:$N$141,0))),INDEX(日常水質!$I$190:$N$190,MATCH($A12,日常水質!$I$187:$N$187,0))),"") | F12: =IFERROR(IFERROR(IFERROR(IFERROR(IFERROR(INDEX(日常水質!$I$8:$N$8,MATCH($A12,日常水質!$I$3:$N$3,0)),INDEX(日常水質!$I$54:$N$54,MATCH($A12,日常水質!$I$49:$N$49,0))),INDEX(日常水質!$I$100:$N$100,MATCH($A12,日常水質!$I$95:$N$95,0))),INDEX(日常水質!$I$146:$N$146,MATCH($A12,日常水質!$I$141:$N$141,0))),INDEX(日常水質!$I$192:$N$192,MATCH($A12,日常水質!$I$187:$N$187,0))),"") | J12: =IFERROR(IFERROR(IFERROR(IFERROR(IFERROR(INDEX(日常水質!$I$10:$N$10,MATCH($A12,日常水質!$I$3:$N$3,0)),INDEX(日常水質!$I$56:$N$56,MATCH($A12,日常水質!$I$49:$N$49,0))),INDEX(日常水質!$I$102:$N$102,MATCH($A12,日常水質!$I$95:$N$95,0))),INDEX(日常水質!$I$148:$N$148,MATCH($A12,日常水質!$I$141:$N$141,0))),INDEX(日常水質!$I$194:$N$194,MATCH($A12,日常水質!$I$187:$N$187,0))),"") | K12: =IF(J12="","",IFERROR((J12-LOOKUP(2,1/(J$6:J11<>""),J$6:J11))/(A12-LOOKUP(2,1/(J$6:J11<>""),A$6:A11)),"")) | L12: =IFERROR(IFERROR(IFERROR(IFERROR(IFERROR(INDEX(日常水質!$I$11:$N$11,MATCH($A12,日常水質!$I$3:$N$3,0)),INDEX(日常水質!$I$57:$N$57,MATCH($A12,日常水質!$I$49:$N$49,0))),INDEX(日常水質!$I$103:$N$103,MATCH($A12,日常水質!$I$95:$N$95,0))),INDEX(日常水質!$I$149:$N$149,MATCH($A12,日常水質!$I$141:$N$141,0))),INDEX(日常水質!$I$195:$N$195,MATCH($A12,日常水質!$I$187:$N$187,0))),"") | M12: =IF(L12="","",IFERROR((L12-LOOKUP(2,1/(L$6:L11<>""),L$6:L11))/(A12-LOOKUP(2,1/(L$6:L11<>""),A$6:A11)),"")) | N12: =IFERROR(IFERROR(IFERROR(IFERROR(IFERROR(INDEX(日常水質!$I$12:$N$12,MATCH($A12,日常水質!$I$3:$N$3,0)),INDEX(日常水質!$I$58:$N$58,MATCH($A12,日常水質!$I$49:$N$49,0))),INDEX(日常水質!$I$104:$N$104,MATCH($A12,日常水質!$I$95:$N$95,0))),INDEX(日常水質!$I$150:$N$150,MATCH($A12,日常水質!$I$141:$N$141,0))),INDEX(日常水質!$I$196:$N$196,MATCH($A12,日常水質!$I$187:$N$187,0))),"")
A13: =IF(ISNUMBER(A12),IF(MONTH(A12+1)=MONTH($A$6),A12+1,""),"") | B13: =IF(ISNUMBER(A13),A13,"") | C13: =IFERROR(IFERROR(IFERROR(IFERROR(IFERROR(INDEX(日常水質!$I$4:$N$4,MATCH($A13,日常水質!$I$3:$N$3,0)),INDEX(日常水質!$I$50:$N$50,MATCH($A13,日常水質!$I$49:$N$49,0))),INDEX(日常水質!$I$96:$N$96,MATCH($A13,日常水質!$I$95:$N$95,0))),INDEX(日常水質!$I$142:$N$142,MATCH($A13,日常水質!$I$141:$N$141,0))),INDEX(日常水質!$I$188:$N$188,MATCH($A13,日常水質!$I$187:$N$187,0))),"") | D13: =IFERROR(IFERROR(IFERROR(IFERROR(IFERROR(INDEX(日常水質!$I$5:$N$5,MATCH($A13,日常水質!$I$3:$N$3,0)),INDEX(日常水質!$I$51:$N$51,MATCH($A13,日常水質!$I$49:$N$49,0))),INDEX(日常水質!$I$97:$N$97,MATCH($A13,日常水質!$I$95:$N$95,0))),INDEX(日常水質!$I$143:$N$143,MATCH($A13,日常水質!$I$141:$N$141,0))),INDEX(日常水質!$I$189:$N$189,MATCH($A13,日常水質!$I$187:$N$187,0))),"") | E13: =IFERROR(IFERROR(IFERROR(IFERROR(IFERROR(INDEX(日常水質!$I$6:$N$6,MATCH($A13,日常水質!$I$3:$N$3,0)),INDEX(日常水質!$I$52:$N$52,MATCH($A13,日常水質!$I$49:$N$49,0))),INDEX(日常水質!$I$98:$N$98,MATCH($A13,日常水質!$I$95:$N$95,0))),INDEX(日常水質!$I$144:$N$144,MATCH($A13,日常水質!$I$141:$N$141,0))),INDEX(日常水質!$I$190:$N$190,MATCH($A13,日常水質!$I$187:$N$187,0))),"") | F13: =IFERROR(IFERROR(IFERROR(IFERROR(IFERROR(INDEX(日常水質!$I$8:$N$8,MATCH($A13,日常水質!$I$3:$N$3,0)),INDEX(日常水質!$I$54:$N$54,MATCH($A13,日常水質!$I$49:$N$49,0))),INDEX(日常水質!$I$100:$N$100,MATCH($A13,日常水質!$I$95:$N$95,0))),INDEX(日常水質!$I$146:$N$146,MATCH($A13,日常水質!$I$141:$N$141,0))),INDEX(日常水質!$I$192:$N$192,MATCH($A13,日常水質!$I$187:$N$187,0))),"") | J13: =IFERROR(IFERROR(IFERROR(IFERROR(IFERROR(INDEX(日常水質!$I$10:$N$10,MATCH($A13,日常水質!$I$3:$N$3,0)),INDEX(日常水質!$I$56:$N$56,MATCH($A13,日常水質!$I$49:$N$49,0))),INDEX(日常水質!$I$102:$N$102,MATCH($A13,日常水質!$I$95:$N$95,0))),INDEX(日常水質!$I$148:$N$148,MATCH($A13,日常水質!$I$141:$N$141,0))),INDEX(日常水質!$I$194:$N$194,MATCH($A13,日常水質!$I$187:$N$187,0))),"") | K13: =IF(J13="","",IFERROR((J13-LOOKUP(2,1/(J$6:J12<>""),J$6:J12))/(A13-LOOKUP(2,1/(J$6:J12<>""),A$6:A12)),"")) | L13: =IFERROR(IFERROR(IFERROR(IFERROR(IFERROR(INDEX(日常水質!$I$11:$N$11,MATCH($A13,日常水質!$I$3:$N$3,0)),INDEX(日常水質!$I$57:$N$57,MATCH($A13,日常水質!$I$49:$N$49,0))),INDEX(日常水質!$I$103:$N$103,MATCH($A13,日常水質!$I$95:$N$95,0))),INDEX(日常水質!$I$149:$N$149,MATCH($A13,日常水質!$I$141:$N$141,0))),INDEX(日常水質!$I$195:$N$195,MATCH($A13,日常水質!$I$187:$N$187,0))),"") | M13: =IF(L13="","",IFERROR((L13-LOOKUP(2,1/(L$6:L12<>""),L$6:L12))/(A13-LOOKUP(2,1/(L$6:L12<>""),A$6:A12)),"")) | N13: =IFERROR(IFERROR(IFERROR(IFERROR(IFERROR(INDEX(日常水質!$I$12:$N$12,MATCH($A13,日常水質!$I$3:$N$3,0)),INDEX(日常水質!$I$58:$N$58,MATCH($A13,日常水質!$I$49:$N$49,0))),INDEX(日常水質!$I$104:$N$104,MATCH($A13,日常水質!$I$95:$N$95,0))),INDEX(日常水質!$I$150:$N$150,MATCH($A13,日常水質!$I$141:$N$141,0))),INDEX(日常水質!$I$196:$N$196,MATCH($A13,日常水質!$I$187:$N$187,0))),"")
A14: =IF(ISNUMBER(A13),IF(MONTH(A13+1)=MONTH($A$6),A13+1,""),"") | B14: =IF(ISNUMBER(A14),A14,"") | C14: =IFERROR(IFERROR(IFERROR(IFERROR(IFERROR(INDEX(日常水質!$I$4:$N$4,MATCH($A14,日常水質!$I$3:$N$3,0)),INDEX(日常水質!$I$50:$N$50,MATCH($A14,日常水質!$I$49:$N$49,0))),INDEX(日常水質!$I$96:$N$96,MATCH($A14,日常水質!$I$95:$N$95,0))),INDEX(日常水質!$I$142:$N$142,MATCH($A14,日常水質!$I$141:$N$141,0))),INDEX(日常水質!$I$188:$N$188,MATCH($A14,日常水質!$I$187:$N$187,0))),"") | D14: =IFERROR(IFERROR(IFERROR(IFERROR(IFERROR(INDEX(日常水質!$I$5:$N$5,MATCH($A14,日常水質!$I$3:$N$3,0)),INDEX(日常水質!$I$51:$N$51,MATCH($A14,日常水質!$I$49:$N$49,0))),INDEX(日常水質!$I$97:$N$97,MATCH($A14,日常水質!$I$95:$N$95,0))),INDEX(日常水質!$I$143:$N$143,MATCH($A14,日常水質!$I$141:$N$141,0))),INDEX(日常水質!$I$189:$N$189,MATCH($A14,日常水質!$I$187:$N$187,0))),"") | E14: =IFERROR(IFERROR(IFERROR(IFERROR(IFERROR(INDEX(日常水質!$I$6:$N$6,MATCH($A14,日常水質!$I$3:$N$3,0)),INDEX(日常水質!$I$52:$N$52,MATCH($A14,日常水質!$I$49:$N$49,0))),INDEX(日常水質!$I$98:$N$98,MATCH($A14,日常水質!$I$95:$N$95,0))),INDEX(日常水質!$I$144:$N$144,MATCH($A14,日常水質!$I$141:$N$141,0))),INDEX(日常水質!$I$190:$N$190,MATCH($A14,日常水質!$I$187:$N$187,0))),"") | F14: =IFERROR(IFERROR(IFERROR(IFERROR(IFERROR(INDEX(日常水質!$I$8:$N$8,MATCH($A14,日常水質!$I$3:$N$3,0)),INDEX(日常水質!$I$54:$N$54,MATCH($A14,日常水質!$I$49:$N$49,0))),INDEX(日常水質!$I$100:$N$100,MATCH($A14,日常水質!$I$95:$N$95,0))),INDEX(日常水質!$I$146:$N$146,MATCH($A14,日常水質!$I$141:$N$141,0))),INDEX(日常水質!$I$192:$N$192,MATCH($A14,日常水質!$I$187:$N$187,0))),"") | J14: =IFERROR(IFERROR(IFERROR(IFERROR(IFERROR(INDEX(日常水質!$I$10:$N$10,MATCH($A14,日常水質!$I$3:$N$3,0)),INDEX(日常水質!$I$56:$N$56,MATCH($A14,日常水質!$I$49:$N$49,0))),INDEX(日常水質!$I$102:$N$102,MATCH($A14,日常水質!$I$95:$N$95,0))),INDEX(日常水質!$I$148:$N$148,MATCH($A14,日常水質!$I$141:$N$141,0))),INDEX(日常水質!$I$194:$N$194,MATCH($A14,日常水質!$I$187:$N$187,0))),"") | K14: =IF(J14="","",IFERROR((J14-LOOKUP(2,1/(J$6:J13<>""),J$6:J13))/(A14-LOOKUP(2,1/(J$6:J13<>""),A$6:A13)),"")) | L14: =IFERROR(IFERROR(IFERROR(IFERROR(IFERROR(INDEX(日常水質!$I$11:$N$11,MATCH($A14,日常水質!$I$3:$N$3,0)),INDEX(日常水質!$I$57:$N$57,MATCH($A14,日常水質!$I$49:$N$49,0))),INDEX(日常水質!$I$103:$N$103,MATCH($A14,日常水質!$I$95:$N$95,0))),INDEX(日常水質!$I$149:$N$149,MATCH($A14,日常水質!$I$141:$N$141,0))),INDEX(日常水質!$I$195:$N$195,MATCH($A14,日常水質!$I$187:$N$187,0))),"") | M14: =IF(L14="","",IFERROR((L14-LOOKUP(2,1/(L$6:L13<>""),L$6:L13))/(A14-LOOKUP(2,1/(L$6:L13<>""),A$6:A13)),"")) | N14: =IFERROR(IFERROR(IFERROR(IFERROR(IFERROR(INDEX(日常水質!$I$12:$N$12,MATCH($A14,日常水質!$I$3:$N$3,0)),INDEX(日常水質!$I$58:$N$58,MATCH($A14,日常水質!$I$49:$N$49,0))),INDEX(日常水質!$I$104:$N$104,MATCH($A14,日常水質!$I$95:$N$95,0))),INDEX(日常水質!$I$150:$N$150,MATCH($A14,日常水質!$I$141:$N$141,0))),INDEX(日常水質!$I$196:$N$196,MATCH($A14,日常水質!$I$187:$N$187,0))),"")
A15: =IF(ISNUMBER(A14),IF(MONTH(A14+1)=MONTH($A$6),A14+1,""),"") | B15: =IF(ISNUMBER(A15),A15,"") | C15: =IFERROR(IFERROR(IFERROR(IFERROR(IFERROR(INDEX(日常水質!$I$4:$N$4,MATCH($A15,日常水質!$I$3:$N$3,0)),INDEX(日常水質!$I$50:$N$50,MATCH($A15,日常水質!$I$49:$N$49,0))),INDEX(日常水質!$I$96:$N$96,MATCH($A15,日常水質!$I$95:$N$95,0))),INDEX(日常水質!$I$142:$N$142,MATCH($A15,日常水質!$I$141:$N$141,0))),INDEX(日常水質!$I$188:$N$188,MATCH($A15,日常水質!$I$187:$N$187,0))),"") | D15: =IFERROR(IFERROR(IFERROR(IFERROR(IFERROR(INDEX(日常水質!$I$5:$N$5,MATCH($A15,日常水質!$I$3:$N$3,0)),INDEX(日常水質!$I$51:$N$51,MATCH($A15,日常水質!$I$49:$N$49,0))),INDEX(日常水質!$I$97:$N$97,MATCH($A15,日常水質!$I$95:$N$95,0))),INDEX(日常水質!$I$143:$N$143,MATCH($A15,日常水質!$I$141:$N$141,0))),INDEX(日常水質!$I$189:$N$189,MATCH($A15,日常水質!$I$187:$N$187,0))),"") | E15: =IFERROR(IFERROR(IFERROR(IFERROR(IFERROR(INDEX(日常水質!$I$6:$N$6,MATCH($A15,日常水質!$I$3:$N$3,0)),INDEX(日常水質!$I$52:$N$52,MATCH($A15,日常水質!$I$49:$N$49,0))),INDEX(日常水質!$I$98:$N$98,MATCH($A15,日常水質!$I$95:$N$95,0))),INDEX(日常水質!$I$144:$N$144,MATCH($A15,日常水質!$I$141:$N$141,0))),INDEX(日常水質!$I$190:$N$190,MATCH($A15,日常水質!$I$187:$N$187,0))),"") | F15: =IFERROR(IFERROR(IFERROR(IFERROR(IFERROR(INDEX(日常水質!$I$8:$N$8,MATCH($A15,日常水質!$I$3:$N$3,0)),INDEX(日常水質!$I$54:$N$54,MATCH($A15,日常水質!$I$49:$N$49,0))),INDEX(日常水質!$I$100:$N$100,MATCH($A15,日常水質!$I$95:$N$95,0))),INDEX(日常水質!$I$146:$N$146,MATCH($A15,日常水質!$I$141:$N$141,0))),INDEX(日常水質!$I$192:$N$192,MATCH($A15,日常水質!$I$187:$N$187,0))),"") | J15: =IFERROR(IFERROR(IFERROR(IFERROR(IFERROR(INDEX(日常水質!$I$10:$N$10,MATCH($A15,日常水質!$I$3:$N$3,0)),INDEX(日常水質!$I$56:$N$56,MATCH($A15,日常水質!$I$49:$N$49,0))),INDEX(日常水質!$I$102:$N$102,MATCH($A15,日常水質!$I$95:$N$95,0))),INDEX(日常水質!$I$148:$N$148,MATCH($A15,日常水質!$I$141:$N$141,0))),INDEX(日常水質!$I$194:$N$194,MATCH($A15,日常水質!$I$187:$N$187,0))),"") | K15: =IF(J15="","",IFERROR((J15-LOOKUP(2,1/(J$6:J14<>""),J$6:J14))/(A15-LOOKUP(2,1/(J$6:J14<>""),A$6:A14)),"")) | L15: =IFERROR(IFERROR(IFERROR(IFERROR(IFERROR(INDEX(日常水質!$I$11:$N$11,MATCH($A15,日常水質!$I$3:$N$3,0)),INDEX(日常水質!$I$57:$N$57,MATCH($A15,日常水質!$I$49:$N$49,0))),INDEX(日常水質!$I$103:$N$103,MATCH($A15,日常水質!$I$95:$N$95,0))),INDEX(日常水質!$I$149:$N$149,MATCH($A15,日常水質!$I$141:$N$141,0))),INDEX(日常水質!$I$195:$N$195,MATCH($A15,日常水質!$I$187:$N$187,0))),"") | M15: =IF(L15="","",IFERROR((L15-LOOKUP(2,1/(L$6:L14<>""),L$6:L14))/(A15-LOOKUP(2,1/(L$6:L14<>""),A$6:A14)),"")) | N15: =IFERROR(IFERROR(IFERROR(IFERROR(IFERROR(INDEX(日常水質!$I$12:$N$12,MATCH($A15,日常水質!$I$3:$N$3,0)),INDEX(日常水質!$I$58:$N$58,MATCH($A15,日常水質!$I$49:$N$49,0))),INDEX(日常水質!$I$104:$N$104,MATCH($A15,日常水質!$I$95:$N$95,0))),INDEX(日常水質!$I$150:$N$150,MATCH($A15,日常水質!$I$141:$N$141,0))),INDEX(日常水質!$I$196:$N$196,MATCH($A15,日常水質!$I$187:$N$187,0))),"")
A16: =IF(ISNUMBER(A15),IF(MONTH(A15+1)=MONTH($A$6),A15+1,""),"") | B16: =IF(ISNUMBER(A16),A16,"") | C16: =IFERROR(IFERROR(IFERROR(IFERROR(IFERROR(INDEX(日常水質!$I$4:$N$4,MATCH($A16,日常水質!$I$3:$N$3,0)),INDEX(日常水質!$I$50:$N$50,MATCH($A16,日常水質!$I$49:$N$49,0))),INDEX(日常水質!$I$96:$N$96,MATCH($A16,日常水質!$I$95:$N$95,0))),INDEX(日常水質!$I$142:$N$142,MATCH($A16,日常水質!$I$141:$N$141,0))),INDEX(日常水質!$I$188:$N$188,MATCH($A16,日常水質!$I$187:$N$187,0))),"") | D16: =IFERROR(IFERROR(IFERROR(IFERROR(IFERROR(INDEX(日常水質!$I$5:$N$5,MATCH($A16,日常水質!$I$3:$N$3,0)),INDEX(日常水質!$I$51:$N$51,MATCH($A16,日常水質!$I$49:$N$49,0))),INDEX(日常水質!$I$97:$N$97,MATCH($A16,日常水質!$I$95:$N$95,0))),INDEX(日常水質!$I$143:$N$143,MATCH($A16,日常水質!$I$141:$N$141,0))),INDEX(日常水質!$I$189:$N$189,MATCH($A16,日常水質!$I$187:$N$187,0))),"") | E16: =IFERROR(IFERROR(IFERROR(IFERROR(IFERROR(INDEX(日常水質!$I$6:$N$6,MATCH($A16,日常水質!$I$3:$N$3,0)),INDEX(日常水質!$I$52:$N$52,MATCH($A16,日常水質!$I$49:$N$49,0))),INDEX(日常水質!$I$98:$N$98,MATCH($A16,日常水質!$I$95:$N$95,0))),INDEX(日常水質!$I$144:$N$144,MATCH($A16,日常水質!$I$141:$N$141,0))),INDEX(日常水質!$I$190:$N$190,MATCH($A16,日常水質!$I$187:$N$187,0))),"") | F16: =IFERROR(IFERROR(IFERROR(IFERROR(IFERROR(INDEX(日常水質!$I$8:$N$8,MATCH($A16,日常水質!$I$3:$N$3,0)),INDEX(日常水質!$I$54:$N$54,MATCH($A16,日常水質!$I$49:$N$49,0))),INDEX(日常水質!$I$100:$N$100,MATCH($A16,日常水質!$I$95:$N$95,0))),INDEX(日常水質!$I$146:$N$146,MATCH($A16,日常水質!$I$141:$N$141,0))),INDEX(日常水質!$I$192:$N$192,MATCH($A16,日常水質!$I$187:$N$187,0))),"") | J16: =IFERROR(IFERROR(IFERROR(IFERROR(IFERROR(INDEX(日常水質!$I$10:$N$10,MATCH($A16,日常水質!$I$3:$N$3,0)),INDEX(日常水質!$I$56:$N$56,MATCH($A16,日常水質!$I$49:$N$49,0))),INDEX(日常水質!$I$102:$N$102,MATCH($A16,日常水質!$I$95:$N$95,0))),INDEX(日常水質!$I$148:$N$148,MATCH($A16,日常水質!$I$141:$N$141,0))),INDEX(日常水質!$I$194:$N$194,MATCH($A16,日常水質!$I$187:$N$187,0))),"") | K16: =IF(J16="","",IFERROR((J16-LOOKUP(2,1/(J$6:J15<>""),J$6:J15))/(A16-LOOKUP(2,1/(J$6:J15<>""),A$6:A15)),"")) | L16: =IFERROR(IFERROR(IFERROR(IFERROR(IFERROR(INDEX(日常水質!$I$11:$N$11,MATCH($A16,日常水質!$I$3:$N$3,0)),INDEX(日常水質!$I$57:$N$57,MATCH($A16,日常水質!$I$49:$N$49,0))),INDEX(日常水質!$I$103:$N$103,MATCH($A16,日常水質!$I$95:$N$95,0))),INDEX(日常水質!$I$149:$N$149,MATCH($A16,日常水質!$I$141:$N$141,0))),INDEX(日常水質!$I$195:$N$195,MATCH($A16,日常水質!$I$187:$N$187,0))),"") | M16: =IF(L16="","",IFERROR((L16-LOOKUP(2,1/(L$6:L15<>""),L$6:L15))/(A16-LOOKUP(2,1/(L$6:L15<>""),A$6:A15)),"")) | N16: =IFERROR(IFERROR(IFERROR(IFERROR(IFERROR(INDEX(日常水質!$I$12:$N$12,MATCH($A16,日常水質!$I$3:$N$3,0)),INDEX(日常水質!$I$58:$N$58,MATCH($A16,日常水質!$I$49:$N$49,0))),INDEX(日常水質!$I$104:$N$104,MATCH($A16,日常水質!$I$95:$N$95,0))),INDEX(日常水質!$I$150:$N$150,MATCH($A16,日常水質!$I$141:$N$141,0))),INDEX(日常水質!$I$196:$N$196,MATCH($A16,日常水質!$I$187:$N$187,0))),"")
A17: =IF(ISNUMBER(A16),IF(MONTH(A16+1)=MONTH($A$6),A16+1,""),"") | B17: =IF(ISNUMBER(A17),A17,"") | C17: =IFERROR(IFERROR(IFERROR(IFERROR(IFERROR(INDEX(日常水質!$I$4:$N$4,MATCH($A17,日常水質!$I$3:$N$3,0)),INDEX(日常水質!$I$50:$N$50,MATCH($A17,日常水質!$I$49:$N$49,0))),INDEX(日常水質!$I$96:$N$96,MATCH($A17,日常水質!$I$95:$N$95,0))),INDEX(日常水質!$I$142:$N$142,MATCH($A17,日常水質!$I$141:$N$141,0))),INDEX(日常水質!$I$188:$N$188,MATCH($A17,日常水質!$I$187:$N$187,0))),"") | D17: =IFERROR(IFERROR(IFERROR(IFERROR(IFERROR(INDEX(日常水質!$I$5:$N$5,MATCH($A17,日常水質!$I$3:$N$3,0)),INDEX(日常水質!$I$51:$N$51,MATCH($A17,日常水質!$I$49:$N$49,0))),INDEX(日常水質!$I$97:$N$97,MATCH($A17,日常水質!$I$95:$N$95,0))),INDEX(日常水質!$I$143:$N$143,MATCH($A17,日常水質!$I$141:$N$141,0))),INDEX(日常水質!$I$189:$N$189,MATCH($A17,日常水質!$I$187:$N$187,0))),"") | E17: =IFERROR(IFERROR(IFERROR(IFERROR(IFERROR(INDEX(日常水質!$I$6:$N$6,MATCH($A17,日常水質!$I$3:$N$3,0)),INDEX(日常水質!$I$52:$N$52,MATCH($A17,日常水質!$I$49:$N$49,0))),INDEX(日常水質!$I$98:$N$98,MATCH($A17,日常水質!$I$95:$N$95,0))),INDEX(日常水質!$I$144:$N$144,MATCH($A17,日常水質!$I$141:$N$141,0))),INDEX(日常水質!$I$190:$N$190,MATCH($A17,日常水質!$I$187:$N$187,0))),"") | F17: =IFERROR(IFERROR(IFERROR(IFERROR(IFERROR(INDEX(日常水質!$I$8:$N$8,MATCH($A17,日常水質!$I$3:$N$3,0)),INDEX(日常水質!$I$54:$N$54,MATCH($A17,日常水質!$I$49:$N$49,0))),INDEX(日常水質!$I$100:$N$100,MATCH($A17,日常水質!$I$95:$N$95,0))),INDEX(日常水質!$I$146:$N$146,MATCH($A17,日常水質!$I$141:$N$141,0))),INDEX(日常水質!$I$192:$N$192,MATCH($A17,日常水質!$I$187:$N$187,0))),"") | J17: =IFERROR(IFERROR(IFERROR(IFERROR(IFERROR(INDEX(日常水質!$I$10:$N$10,MATCH($A17,日常水質!$I$3:$N$3,0)),INDEX(日常水質!$I$56:$N$56,MATCH($A17,日常水質!$I$49:$N$49,0))),INDEX(日常水質!$I$102:$N$102,MATCH($A17,日常水質!$I$95:$N$95,0))),INDEX(日常水質!$I$148:$N$148,MATCH($A17,日常水質!$I$141:$N$141,0))),INDEX(日常水質!$I$194:$N$194,MATCH($A17,日常水質!$I$187:$N$187,0))),"") | K17: =IF(J17="","",IFERROR((J17-LOOKUP(2,1/(J$6:J16<>""),J$6:J16))/(A17-LOOKUP(2,1/(J$6:J16<>""),A$6:A16)),"")) | L17: =IFERROR(IFERROR(IFERROR(IFERROR(IFERROR(INDEX(日常水質!$I$11:$N$11,MATCH($A17,日常水質!$I$3:$N$3,0)),INDEX(日常水質!$I$57:$N$57,MATCH($A17,日常水質!$I$49:$N$49,0))),INDEX(日常水質!$I$103:$N$103,MATCH($A17,日常水質!$I$95:$N$95,0))),INDEX(日常水質!$I$149:$N$149,MATCH($A17,日常水質!$I$141:$N$141,0))),INDEX(日常水質!$I$195:$N$195,MATCH($A17,日常水質!$I$187:$N$187,0))),"") | M17: =IF(L17="","",IFERROR((L17-LOOKUP(2,1/(L$6:L16<>""),L$6:L16))/(A17-LOOKUP(2,1/(L$6:L16<>""),A$6:A16)),"")) | N17: =IFERROR(IFERROR(IFERROR(IFERROR(IFERROR(INDEX(日常水質!$I$12:$N$12,MATCH($A17,日常水質!$I$3:$N$3,0)),INDEX(日常水質!$I$58:$N$58,MATCH($A17,日常水質!$I$49:$N$49,0))),INDEX(日常水質!$I$104:$N$104,MATCH($A17,日常水質!$I$95:$N$95,0))),INDEX(日常水質!$I$150:$N$150,MATCH($A17,日常水質!$I$141:$N$141,0))),INDEX(日常水質!$I$196:$N$196,MATCH($A17,日常水質!$I$187:$N$187,0))),"")
A18: =IF(ISNUMBER(A17),IF(MONTH(A17+1)=MONTH($A$6),A17+1,""),"") | B18: =IF(ISNUMBER(A18),A18,"") | C18: =IFERROR(IFERROR(IFERROR(IFERROR(IFERROR(INDEX(日常水質!$I$4:$N$4,MATCH($A18,日常水質!$I$3:$N$3,0)),INDEX(日常水質!$I$50:$N$50,MATCH($A18,日常水質!$I$49:$N$49,0))),INDEX(日常水質!$I$96:$N$96,MATCH($A18,日常水質!$I$95:$N$95,0))),INDEX(日常水質!$I$142:$N$142,MATCH($A18,日常水質!$I$141:$N$141,0))),INDEX(日常水質!$I$188:$N$188,MATCH($A18,日常水質!$I$187:$N$187,0))),"") | D18: =IFERROR(IFERROR(IFERROR(IFERROR(IFERROR(INDEX(日常水質!$I$5:$N$5,MATCH($A18,日常水質!$I$3:$N$3,0)),INDEX(日常水質!$I$51:$N$51,MATCH($A18,日常水質!$I$49:$N$49,0))),INDEX(日常水質!$I$97:$N$97,MATCH($A18,日常水質!$I$95:$N$95,0))),INDEX(日常水質!$I$143:$N$143,MATCH($A18,日常水質!$I$141:$N$141,0))),INDEX(日常水質!$I$189:$N$189,MATCH($A18,日常水質!$I$187:$N$187,0))),"") | E18: =IFERROR(IFERROR(IFERROR(IFERROR(IFERROR(INDEX(日常水質!$I$6:$N$6,MATCH($A18,日常水質!$I$3:$N$3,0)),INDEX(日常水質!$I$52:$N$52,MATCH($A18,日常水質!$I$49:$N$49,0))),INDEX(日常水質!$I$98:$N$98,MATCH($A18,日常水質!$I$95:$N$95,0))),INDEX(日常水質!$I$144:$N$144,MATCH($A18,日常水質!$I$141:$N$141,0))),INDEX(日常水質!$I$190:$N$190,MATCH($A18,日常水質!$I$187:$N$187,0))),"") | F18: =IFERROR(IFERROR(IFERROR(IFERROR(IFERROR(INDEX(日常水質!$I$8:$N$8,MATCH($A18,日常水質!$I$3:$N$3,0)),INDEX(日常水質!$I$54:$N$54,MATCH($A18,日常水質!$I$49:$N$49,0))),INDEX(日常水質!$I$100:$N$100,MATCH($A18,日常水質!$I$95:$N$95,0))),INDEX(日常水質!$I$146:$N$146,MATCH($A18,日常水質!$I$141:$N$141,0))),INDEX(日常水質!$I$192:$N$192,MATCH($A18,日常水質!$I$187:$N$187,0))),"") | J18: =IFERROR(IFERROR(IFERROR(IFERROR(IFERROR(INDEX(日常水質!$I$10:$N$10,MATCH($A18,日常水質!$I$3:$N$3,0)),INDEX(日常水質!$I$56:$N$56,MATCH($A18,日常水質!$I$49:$N$49,0))),INDEX(日常水質!$I$102:$N$102,MATCH($A18,日常水質!$I$95:$N$95,0))),INDEX(日常水質!$I$148:$N$148,MATCH($A18,日常水質!$I$141:$N$141,0))),INDEX(日常水質!$I$194:$N$194,MATCH($A18,日常水質!$I$187:$N$187,0))),"") | K18: =IF(J18="","",IFERROR((J18-LOOKUP(2,1/(J$6:J17<>""),J$6:J17))/(A18-LOOKUP(2,1/(J$6:J17<>""),A$6:A17)),"")) | L18: =IFERROR(IFERROR(IFERROR(IFERROR(IFERROR(INDEX(日常水質!$I$11:$N$11,MATCH($A18,日常水質!$I$3:$N$3,0)),INDEX(日常水質!$I$57:$N$57,MATCH($A18,日常水質!$I$49:$N$49,0))),INDEX(日常水質!$I$103:$N$103,MATCH($A18,日常水質!$I$95:$N$95,0))),INDEX(日常水質!$I$149:$N$149,MATCH($A18,日常水質!$I$141:$N$141,0))),INDEX(日常水質!$I$195:$N$195,MATCH($A18,日常水質!$I$187:$N$187,0))),"") | M18: =IF(L18="","",IFERROR((L18-LOOKUP(2,1/(L$6:L17<>""),L$6:L17))/(A18-LOOKUP(2,1/(L$6:L17<>""),A$6:A17)),"")) | N18: =IFERROR(IFERROR(IFERROR(IFERROR(IFERROR(INDEX(日常水質!$I$12:$N$12,MATCH($A18,日常水質!$I$3:$N$3,0)),INDEX(日常水質!$I$58:$N$58,MATCH($A18,日常水質!$I$49:$N$49,0))),INDEX(日常水質!$I$104:$N$104,MATCH($A18,日常水質!$I$95:$N$95,0))),INDEX(日常水質!$I$150:$N$150,MATCH($A18,日常水質!$I$141:$N$141,0))),INDEX(日常水質!$I$196:$N$196,MATCH($A18,日常水質!$I$187:$N$187,0))),"")
... A36: =IF(ISNUMBER(A35),IF(MONTH(A35+1)=MONTH($A$6),A35+1,""),"") | B36: =IF(ISNUMBER(A36),A36,"") | C36: =IFERROR(IFERROR(IFERROR(IFERROR(IFERROR(INDEX(日常水質!$I$4:$N$4,MATCH($A36,日常水質!$I$3:$N$3,0)),INDEX(日常水質!$I$50:$N$50,MATCH($A36,日常水質!$I$49:$N$49,0))),INDEX(日常水質!$I$96:$N$96,MATCH($A36,日常水質!$I$95:$N$95,0))),INDEX(日常水質!$I$142:$N$142,MATCH($A36,日常水質!$I$141:$N$141,0))),INDEX(日常水質!$I$188:$N$188,MATCH($A36,日常水質!$I$187:$N$187,0))),"") | D36: =IFERROR(IFERROR(IFERROR(IFERROR(IFERROR(INDEX(日常水質!$I$5:$N$5,MATCH($A36,日常水質!$I$3:$N$3,0)),INDEX(日常水質!$I$51:$N$51,MATCH($A36,日常水質!$I$49:$N$49,0))),INDEX(日常水質!$I$97:$N$97,MATCH($A36,日常水質!$I$95:$N$95,0))),INDEX(日常水質!$I$143:$N$143,MATCH($A36,日常水質!$I$141:$N$141,0))),INDEX(日常水質!$I$189:$N$189,MATCH($A36,日常水質!$I$187:$N$187,0))),"") | E36: =IFERROR(IFERROR(IFERROR(IFERROR(IFERROR(INDEX(日常水質!$I$6:$N$6,MATCH($A36,日常水質!$I$3:$N$3,0)),INDEX(日常水質!$I$52:$N$52,MATCH($A36,日常水質!$I$49:$N$49,0))),INDEX(日常水質!$I$98:$N$98,MATCH($A36,日常水質!$I$95:$N$95,0))),INDEX(日常水質!$I$144:$N$144,MATCH($A36,日常水質!$I$141:$N$141,0))),INDEX(日常水質!$I$190:$N$190,MATCH($A36,日常水質!$I$187:$N$187,0))),"") | F36: =IFERROR(IFERROR(IFERROR(IFERROR(IFERROR(INDEX(日常水質!$I$8:$N$8,MATCH($A36,日常水質!$I$3:$N$3,0)),INDEX(日常水質!$I$54:$N$54,MATCH($A36,日常水質!$I$49:$N$49,0))),INDEX(日常水質!$I$100:$N$100,MATCH($A36,日常水質!$I$95:$N$95,0))),INDEX(日常水質!$I$146:$N$146,MATCH($A36,日常水質!$I$141:$N$141,0))),INDEX(日常水質!$I$192:$N$192,MATCH($A36,日常水質!$I$187:$N$187,0))),"") | J36: =IFERROR(IFERROR(IFERROR(IFERROR(IFERROR(INDEX(日常水質!$I$10:$N$10,MATCH($A36,日常水質!$I$3:$N$3,0)),INDEX(日常水質!$I$56:$N$56,MATCH($A36,日常水質!$I$49:$N$49,0))),INDEX(日常水質!$I$102:$N$102,MATCH($A36,日常水質!$I$95:$N$95,0))),INDEX(日常水質!$I$148:$N$148,MATCH($A36,日常水質!$I$141:$N$141,0))),INDEX(日常水質!$I$194:$N$194,MATCH($A36,日常水質!$I$187:$N$187,0))),"") | K36: =IF(J36="","",IFERROR((J36-LOOKUP(2,1/(J$6:J35<>""),J$6:J35))/(A36-LOOKUP(2,1/(J$6:J35<>""),A$6:A35)),"")) | L36: =IFERROR(IFERROR(IFERROR(IFERROR(IFERROR(INDEX(日常水質!$I$11:$N$11,MATCH($A36,日常水質!$I$3:$N$3,0)),INDEX(日常水質!$I$57:$N$57,MATCH($A36,日常水質!$I$49:$N$49,0))),INDEX(日常水質!$I$103:$N$103,MATCH($A36,日常水質!$I$95:$N$95,0))),INDEX(日常水質!$I$149:$N$149,MATCH($A36,日常水質!$I$141:$N$141,0))),INDEX(日常水質!$I$195:$N$195,MATCH($A36,日常水質!$I$187:$N$187,0))),"") | M36: =IF(L36="","",IFERROR((L36-LOOKUP(2,1/(L$6:L35<>""),L$6:L35))/(A36-LOOKUP(2,1/(L$6:L35<>""),A$6:A35)),"")) | N36: =IFERROR(IFERROR(IFERROR(IFERROR(IFERROR(INDEX(日常水質!$I$12:$N$12,MATCH($A36,日常水質!$I$3:$N$3,0)),INDEX(日常水質!$I$58:$N$58,MATCH($A36,日常水質!$I$49:$N$49,0))),INDEX(日常水質!$I$104:$N$104,MATCH($A36,日常水質!$I$95:$N$95,0))),INDEX(日常水質!$I$150:$N$150,MATCH($A36,日常水質!$I$141:$N$141,0))),INDEX(日常水質!$I$196:$N$196,MATCH($A36,日常水質!$I$187:$N$187,0))),"")
A37: 最大 | C37: - | D37: - | E37: - | F37: - | G37: =IFERROR(MAX(G6:G36),"") | H37: =IFERROR(MAX(H6:H36),"") | I37: =IFERROR(MAX(I6:I36),"") | J37: - | K37: =IFERROR(MAX(K6:K36),"") | L37: - | M37: =IFERROR(MAX(M6:M36),"") | N37: =IFERROR(MAX(N6:N36),"")
A38: 平均 | C38: - | D38: - | E38: - | F38: - | G38: =IFERROR(AVERAGE(G6:G36),"") | H38: =IFERROR(AVERAGE(H6:H36),"") | I38: =IFERROR(AVERAGE(I6:I36),"") | J38: - | K38: =IFERROR(AVERAGE(K6:K36),"") | L38: - | M38: =IFERROR(AVERAGE(M6:M36),"") | N38: =IFERROR(AVERAGE(N6:N36),"")
A39: 最小 | C39: - | D39: - | E39: - | F39: - | G39: =IFERROR(MIN(G6:G36),"") | H39: =IFERROR(MIN(H6:H36),"") | I39: =IFERROR(MIN(I6:I36),"") | J39: - | K39: =IFERROR(MIN(K6:K36),"") | L39: - | M39: =IFERROR(MIN(M6:M36),"") | N39: =IFERROR(MIN(N6:N36),"")
A40: 合計 | C40: - | D40: - | E40: - | F40: - | G40: =IFERROR(SUM(G6:G36),0) | H40: =IFERROR(SUM(H6:H36),0) | I40: =IFERROR(SUM(I6:I36),0) | J40: - | K40: =IFERROR(SUM(K6:K36),0) | L40: - | M40: =IFERROR(SUM(M6:M36),0) | N40: =IFERROR(SUM(N6:N36),0)

Sheet 水質管理報告
A1: 加計浄化センター水質管理月報（１/２） | O1: =日常電気設備!K1
A3: 日付 | B3: 曜日 | C3: 水温 | G3: PH | K3: 透視度 | N3: MLDO | O3: MLSS | P3: SV30 | Q3: 残留塩素
C4: （５回/週） | G4: （５回/週） | K4: （５回/週） | N4: （５回/週） | O4: （５回/週） | P4: （５回/週） | Q4: （５回/週）
C5: ℃ | G5: ― | K5: cm | N5: ㎎/ℓ | O5: ㎎/ℓ | P5: ％ | Q5: ㎎/ℓ
C6: 流入 | D6: No．１ | E6: No．１ | F6: 放流水 | G6: 流入 | H6: No．１ | I6: No．１ | J6: 放流水 | K6: 流入 | L6: No.1 終沈 | M6: 放流 | N6: No．１ | O6: No．１ | P6: No．１ | Q6: 放流水
D7: ディッチ | E7: 終沈 | H7: ディッチ | I7: 終沈 | N7: ディッチ | O7: ディッチ | P7: ディッチ
A8: =IFERROR(IF(AND(ISNUMBER(日常水質!$P$1),YEAR(日常水質!$P$1)>=2000),DATE(YEAR(日常水質!$P$1),MONTH(日常水質!$P$1),1),NA()),IFERROR(IF(AND(ISNUMBER(日常水質!$I$95),YEAR(日常水質!$I$95)>=2000),DATE(YEAR(日常水質!$I$95),MONTH(日常水質!$I$95),1),NA()),IFERROR(IF(AND(ISNUMBER(日常水質!$I$49),YEAR(日常水質!$I$49)>=2000),DATE(YEAR(日常水質!$I$49),MONTH(日常水質!$I$49),1),NA()),IFERROR(IF(AND(ISNUMBER(日常水質!$I$141),YEAR(日常水質!$I$141)>=2000),DATE(YEAR(日常水質!$I$141),MONTH(日常水質!$I$141),1),NA()),IFERROR(IF(AND(ISNUMBER(日常水質!$I$187),YEAR(日常水質!$I$187)>=2000),DATE(YEAR(日常水質!$I$187),MONTH(日常水質!$I$187),1),NA()),IFERROR(IF(AND(ISNUMBER(日常水質!$I$3),YEAR(日常水質!$I$3)>=2000),DATE(YEAR(日常水質!$I$3),MONTH(日常水質!$I$3),1),NA()),"")))))) | B8: =IF(ISNUMBER(A8),A8,"") | C8: =IFERROR(IFERROR(IFERROR(IFERROR(IFERROR(INDEX(日常水質!$J$16:$N$16,MATCH($A8,日常水質!$J$14:$N$14,0)),INDEX(日常水質!$J$62:$N$62,MATCH($A8,日常水質!$J$60:$N$60,0))),INDEX(日常水質!$J$108:$N$108,MATCH($A8,日常水質!$J$106:$N$106,0))),INDEX(日常水質!$J$154:$N$154,MATCH($A8,日常水質!$J$152:$N$152,0))),INDEX(日常水質!$J$200:$N$200,MATCH($A8,日常水質!$J$198:$N$198,0))),"") | D8: =IFERROR(IFERROR(IFERROR(IFERROR(IFERROR(INDEX(日常水質!$J$17:$N$17,MATCH($A8,日常水質!$J$14:$N$14,0)),INDEX(日常水質!$J$63:$N$63,MATCH($A8,日常水質!$J$60:$N$60,0))),INDEX(日常水質!$J$109:$N$109,MATCH($A8,日常水質!$J$106:$N$106,0))),INDEX(日常水質!$J$155:$N$155,MATCH($A8,日常水質!$J$152:$N$152,0))),INDEX(日常水質!$J$201:$N$201,MATCH($A8,日常水質!$J$198:$N$198,0))),"") | F8: =IFERROR(IFERROR(IFERROR(IFERROR(IFERROR(INDEX(日常水質!$J$18:$N$18,MATCH($A8,日常水質!$J$14:$N$14,0)),INDEX(日常水質!$J$64:$N$64,MATCH($A8,日常水質!$J$60:$N$60,0))),INDEX(日常水質!$J$110:$N$110,MATCH($A8,日常水質!$J$106:$N$106,0))),INDEX(日常水質!$J$156:$N$156,MATCH($A8,日常水質!$J$152:$N$152,0))),INDEX(日常水質!$J$202:$N$202,MATCH($A8,日常水質!$J$198:$N$198,0))),"") | G8: =IFERROR(IFERROR(IFERROR(IFERROR(IFERROR(INDEX(日常水質!$J$27:$N$27,MATCH($A8,日常水質!$J$14:$N$14,0)),INDEX(日常水質!$J$73:$N$73,MATCH($A8,日常水質!$J$60:$N$60,0))),INDEX(日常水質!$J$119:$N$119,MATCH($A8,日常水質!$J$106:$N$106,0))),INDEX(日常水質!$J$165:$N$165,MATCH($A8,日常水質!$J$152:$N$152,0))),INDEX(日常水質!$J$211:$N$211,MATCH($A8,日常水質!$J$198:$N$198,0))),"") | H8: =IFERROR(IFERROR(IFERROR(IFERROR(IFERROR(INDEX(日常水質!$J$28:$N$28,MATCH($A8,日常水質!$J$14:$N$14,0)),INDEX(日常水質!$J$74:$N$74,MATCH($A8,日常水質!$J$60:$N$60,0))),INDEX(日常水質!$J$120:$N$120,MATCH($A8,日常水質!$J$106:$N$106,0))),INDEX(日常水質!$J$166:$N$166,MATCH($A8,日常水質!$J$152:$N$152,0))),INDEX(日常水質!$J$212:$N$212,MATCH($A8,日常水質!$J$198:$N$198,0))),"") | J8: =IFERROR(IFERROR(IFERROR(IFERROR(IFERROR(INDEX(日常水質!$J$29:$N$29,MATCH($A8,日常水質!$J$14:$N$14,0)),INDEX(日常水質!$J$75:$N$75,MATCH($A8,日常水質!$J$60:$N$60,0))),INDEX(日常水質!$J$121:$N$121,MATCH($A8,日常水質!$J$106:$N$106,0))),INDEX(日常水質!$J$167:$N$167,MATCH($A8,日常水質!$J$152:$N$152,0))),INDEX(日常水質!$J$213:$N$213,MATCH($A8,日常水質!$J$198:$N$198,0))),"") | K8: =IFERROR(IFERROR(IFERROR(IFERROR(IFERROR(INDEX(日常水質!$J$22:$N$22,MATCH($A8,日常水質!$J$14:$N$14,0)),INDEX(日常水質!$J$68:$N$68,MATCH($A8,日常水質!$J$60:$N$60,0))),INDEX(日常水質!$J$114:$N$114,MATCH($A8,日常水質!$J$106:$N$106,0))),INDEX(日常水質!$J$160:$N$160,MATCH($A8,日常水質!$J$152:$N$152,0))),INDEX(日常水質!$J$206:$N$206,MATCH($A8,日常水質!$J$198:$N$198,0))),"") | M8: =IFERROR(IFERROR(IFERROR(IFERROR(IFERROR(INDEX(日常水質!$J$23:$N$23,MATCH($A8,日常水質!$J$14:$N$14,0)),INDEX(日常水質!$J$69:$N$69,MATCH($A8,日常水質!$J$60:$N$60,0))),INDEX(日常水質!$J$115:$N$115,MATCH($A8,日常水質!$J$106:$N$106,0))),INDEX(日常水質!$J$161:$N$161,MATCH($A8,日常水質!$J$152:$N$152,0))),INDEX(日常水質!$J$207:$N$207,MATCH($A8,日常水質!$J$198:$N$198,0))),"") | O8: =IFERROR(IFERROR(IFERROR(IFERROR(IFERROR(INDEX(日常水質!$J$34:$N$34,MATCH($A8,日常水質!$J$14:$N$14,0)),INDEX(日常水質!$J$80:$N$80,MATCH($A8,日常水質!$J$60:$N$60,0))),INDEX(日常水質!$J$126:$N$126,MATCH($A8,日常水質!$J$106:$N$106,0))),INDEX(日常水質!$J$172:$N$172,MATCH($A8,日常水質!$J$152:$N$152,0))),INDEX(日常水質!$J$218:$N$218,MATCH($A8,日常水質!$J$198:$N$198,0))),"") | P8: =IFERROR(IFERROR(IFERROR(IFERROR(IFERROR(INDEX(日常水質!$J$32:$N$32,MATCH($A8,日常水質!$J$14:$N$14,0)),INDEX(日常水質!$J$78:$N$78,MATCH($A8,日常水質!$J$60:$N$60,0))),INDEX(日常水質!$J$124:$N$124,MATCH($A8,日常水質!$J$106:$N$106,0))),INDEX(日常水質!$J$170:$N$170,MATCH($A8,日常水質!$J$152:$N$152,0))),INDEX(日常水質!$J$216:$N$216,MATCH($A8,日常水質!$J$198:$N$198,0))),"") | Q8: =IFERROR(IFERROR(IFERROR(IFERROR(IFERROR(INDEX(日常水質!$J$36:$N$36,MATCH($A8,日常水質!$J$14:$N$14,0)),INDEX(日常水質!$J$82:$N$82,MATCH($A8,日常水質!$J$60:$N$60,0))),INDEX(日常水質!$J$128:$N$128,MATCH($A8,日常水質!$J$106:$N$106,0))),INDEX(日常水質!$J$174:$N$174,MATCH($A8,日常水質!$J$152:$N$152,0))),INDEX(日常水質!$J$220:$N$220,MATCH($A8,日常水質!$J$198:$N$198,0))),"")
A9: =IF(ISNUMBER(A8),IF(MONTH(A8+1)=MONTH($A$8),A8+1,""),"") | B9: =IF(ISNUMBER(A9),A9,"") | C9: =IFERROR(IFERROR(IFERROR(IFERROR(IFERROR(INDEX(日常水質!$J$16:$N$16,MATCH($A9,日常水質!$J$14:$N$14,0)),INDEX(日常水質!$J$62:$N$62,MATCH($A9,日常水質!$J$60:$N$60,0))),INDEX(日常水質!$J$108:$N$108,MATCH($A9,日常水質!$J$106:$N$106,0))),INDEX(日常水質!$J$154:$N$154,MATCH($A9,日常水質!$J$152:$N$152,0))),INDEX(日常水質!$J$200:$N$200,MATCH($A9,日常水質!$J$198:$N$198,0))),"") | D9: =IFERROR(IFERROR(IFERROR(IFERROR(IFERROR(INDEX(日常水質!$J$17:$N$17,MATCH($A9,日常水質!$J$14:$N$14,0)),INDEX(日常水質!$J$63:$N$63,MATCH($A9,日常水質!$J$60:$N$60,0))),INDEX(日常水質!$J$109:$N$109,MATCH($A9,日常水質!$J$106:$N$106,0))),INDEX(日常水質!$J$155:$N$155,MATCH($A9,日常水質!$J$152:$N$152,0))),INDEX(日常水質!$J$201:$N$201,MATCH($A9,日常水質!$J$198:$N$198,0))),"") | F9: =IFERROR(IFERROR(IFERROR(IFERROR(IFERROR(INDEX(日常水質!$J$18:$N$18,MATCH($A9,日常水質!$J$14:$N$14,0)),INDEX(日常水質!$J$64:$N$64,MATCH($A9,日常水質!$J$60:$N$60,0))),INDEX(日常水質!$J$110:$N$110,MATCH($A9,日常水質!$J$106:$N$106,0))),INDEX(日常水質!$J$156:$N$156,MATCH($A9,日常水質!$J$152:$N$152,0))),INDEX(日常水質!$J$202:$N$202,MATCH($A9,日常水質!$J$198:$N$198,0))),"") | G9: =IFERROR(IFERROR(IFERROR(IFERROR(IFERROR(INDEX(日常水質!$J$27:$N$27,MATCH($A9,日常水質!$J$14:$N$14,0)),INDEX(日常水質!$J$73:$N$73,MATCH($A9,日常水質!$J$60:$N$60,0))),INDEX(日常水質!$J$119:$N$119,MATCH($A9,日常水質!$J$106:$N$106,0))),INDEX(日常水質!$J$165:$N$165,MATCH($A9,日常水質!$J$152:$N$152,0))),INDEX(日常水質!$J$211:$N$211,MATCH($A9,日常水質!$J$198:$N$198,0))),"") | H9: =IFERROR(IFERROR(IFERROR(IFERROR(IFERROR(INDEX(日常水質!$J$28:$N$28,MATCH($A9,日常水質!$J$14:$N$14,0)),INDEX(日常水質!$J$74:$N$74,MATCH($A9,日常水質!$J$60:$N$60,0))),INDEX(日常水質!$J$120:$N$120,MATCH($A9,日常水質!$J$106:$N$106,0))),INDEX(日常水質!$J$166:$N$166,MATCH($A9,日常水質!$J$152:$N$152,0))),INDEX(日常水質!$J$212:$N$212,MATCH($A9,日常水質!$J$198:$N$198,0))),"") | J9: =IFERROR(IFERROR(IFERROR(IFERROR(IFERROR(INDEX(日常水質!$J$29:$N$29,MATCH($A9,日常水質!$J$14:$N$14,0)),INDEX(日常水質!$J$75:$N$75,MATCH($A9,日常水質!$J$60:$N$60,0))),INDEX(日常水質!$J$121:$N$121,MATCH($A9,日常水質!$J$106:$N$106,0))),INDEX(日常水質!$J$167:$N$167,MATCH($A9,日常水質!$J$152:$N$152,0))),INDEX(日常水質!$J$213:$N$213,MATCH($A9,日常水質!$J$198:$N$198,0))),"") | K9: =IFERROR(IFERROR(IFERROR(IFERROR(IFERROR(INDEX(日常水質!$J$22:$N$22,MATCH($A9,日常水質!$J$14:$N$14,0)),INDEX(日常水質!$J$68:$N$68,MATCH($A9,日常水質!$J$60:$N$60,0))),INDEX(日常水質!$J$114:$N$114,MATCH($A9,日常水質!$J$106:$N$106,0))),INDEX(日常水質!$J$160:$N$160,MATCH($A9,日常水質!$J$152:$N$152,0))),INDEX(日常水質!$J$206:$N$206,MATCH($A9,日常水質!$J$198:$N$198,0))),"") | M9: =IFERROR(IFERROR(IFERROR(IFERROR(IFERROR(INDEX(日常水質!$J$23:$N$23,MATCH($A9,日常水質!$J$14:$N$14,0)),INDEX(日常水質!$J$69:$N$69,MATCH($A9,日常水質!$J$60:$N$60,0))),INDEX(日常水質!$J$115:$N$115,MATCH($A9,日常水質!$J$106:$N$106,0))),INDEX(日常水質!$J$161:$N$161,MATCH($A9,日常水質!$J$152:$N$152,0))),INDEX(日常水質!$J$207:$N$207,MATCH($A9,日常水質!$J$198:$N$198,0))),"") | O9: =IFERROR(IFERROR(IFERROR(IFERROR(IFERROR(INDEX(日常水質!$J$34:$N$34,MATCH($A9,日常水質!$J$14:$N$14,0)),INDEX(日常水質!$J$80:$N$80,MATCH($A9,日常水質!$J$60:$N$60,0))),INDEX(日常水質!$J$126:$N$126,MATCH($A9,日常水質!$J$106:$N$106,0))),INDEX(日常水質!$J$172:$N$172,MATCH($A9,日常水質!$J$152:$N$152,0))),INDEX(日常水質!$J$218:$N$218,MATCH($A9,日常水質!$J$198:$N$198,0))),"") | P9: =IFERROR(IFERROR(IFERROR(IFERROR(IFERROR(INDEX(日常水質!$J$32:$N$32,MATCH($A9,日常水質!$J$14:$N$14,0)),INDEX(日常水質!$J$78:$N$78,MATCH($A9,日常水質!$J$60:$N$60,0))),INDEX(日常水質!$J$124:$N$124,MATCH($A9,日常水質!$J$106:$N$106,0))),INDEX(日常水質!$J$170:$N$170,MATCH($A9,日常水質!$J$152:$N$152,0))),INDEX(日常水質!$J$216:$N$216,MATCH($A9,日常水質!$J$198:$N$198,0))),"") | Q9: =IFERROR(IFERROR(IFERROR(IFERROR(IFERROR(INDEX(日常水質!$J$36:$N$36,MATCH($A9,日常水質!$J$14:$N$14,0)),INDEX(日常水質!$J$82:$N$82,MATCH($A9,日常水質!$J$60:$N$60,0))),INDEX(日常水質!$J$128:$N$128,MATCH($A9,日常水質!$J$106:$N$106,0))),INDEX(日常水質!$J$174:$N$174,MATCH($A9,日常水質!$J$152:$N$152,0))),INDEX(日常水質!$J$220:$N$220,MATCH($A9,日常水質!$J$198:$N$198,0))),"")
A10: =IF(ISNUMBER(A9),IF(MONTH(A9+1)=MONTH($A$8),A9+1,""),"") | B10: =IF(ISNUMBER(A10),A10,"") | C10: =IFERROR(IFERROR(IFERROR(IFERROR(IFERROR(INDEX(日常水質!$J$16:$N$16,MATCH($A10,日常水質!$J$14:$N$14,0)),INDEX(日常水質!$J$62:$N$62,MATCH($A10,日常水質!$J$60:$N$60,0))),INDEX(日常水質!$J$108:$N$108,MATCH($A10,日常水質!$J$106:$N$106,0))),INDEX(日常水質!$J$154:$N$154,MATCH($A10,日常水質!$J$152:$N$152,0))),INDEX(日常水質!$J$200:$N$200,MATCH($A10,日常水質!$J$198:$N$198,0))),"") | D10: =IFERROR(IFERROR(IFERROR(IFERROR(IFERROR(INDEX(日常水質!$J$17:$N$17,MATCH($A10,日常水質!$J$14:$N$14,0)),INDEX(日常水質!$J$63:$N$63,MATCH($A10,日常水質!$J$60:$N$60,0))),INDEX(日常水質!$J$109:$N$109,MATCH($A10,日常水質!$J$106:$N$106,0))),INDEX(日常水質!$J$155:$N$155,MATCH($A10,日常水質!$J$152:$N$152,0))),INDEX(日常水質!$J$201:$N$201,MATCH($A10,日常水質!$J$198:$N$198,0))),"") | F10: =IFERROR(IFERROR(IFERROR(IFERROR(IFERROR(INDEX(日常水質!$J$18:$N$18,MATCH($A10,日常水質!$J$14:$N$14,0)),INDEX(日常水質!$J$64:$N$64,MATCH($A10,日常水質!$J$60:$N$60,0))),INDEX(日常水質!$J$110:$N$110,MATCH($A10,日常水質!$J$106:$N$106,0))),INDEX(日常水質!$J$156:$N$156,MATCH($A10,日常水質!$J$152:$N$152,0))),INDEX(日常水質!$J$202:$N$202,MATCH($A10,日常水質!$J$198:$N$198,0))),"") | G10: =IFERROR(IFERROR(IFERROR(IFERROR(IFERROR(INDEX(日常水質!$J$27:$N$27,MATCH($A10,日常水質!$J$14:$N$14,0)),INDEX(日常水質!$J$73:$N$73,MATCH($A10,日常水質!$J$60:$N$60,0))),INDEX(日常水質!$J$119:$N$119,MATCH($A10,日常水質!$J$106:$N$106,0))),INDEX(日常水質!$J$165:$N$165,MATCH($A10,日常水質!$J$152:$N$152,0))),INDEX(日常水質!$J$211:$N$211,MATCH($A10,日常水質!$J$198:$N$198,0))),"") | H10: =IFERROR(IFERROR(IFERROR(IFERROR(IFERROR(INDEX(日常水質!$J$28:$N$28,MATCH($A10,日常水質!$J$14:$N$14,0)),INDEX(日常水質!$J$74:$N$74,MATCH($A10,日常水質!$J$60:$N$60,0))),INDEX(日常水質!$J$120:$N$120,MATCH($A10,日常水質!$J$106:$N$106,0))),INDEX(日常水質!$J$166:$N$166,MATCH($A10,日常水質!$J$152:$N$152,0))),INDEX(日常水質!$J$212:$N$212,MATCH($A10,日常水質!$J$198:$N$198,0))),"") | J10: =IFERROR(IFERROR(IFERROR(IFERROR(IFERROR(INDEX(日常水質!$J$29:$N$29,MATCH($A10,日常水質!$J$14:$N$14,0)),INDEX(日常水質!$J$75:$N$75,MATCH($A10,日常水質!$J$60:$N$60,0))),INDEX(日常水質!$J$121:$N$121,MATCH($A10,日常水質!$J$106:$N$106,0))),INDEX(日常水質!$J$167:$N$167,MATCH($A10,日常水質!$J$152:$N$152,0))),INDEX(日常水質!$J$213:$N$213,MATCH($A10,日常水質!$J$198:$N$198,0))),"") | K10: =IFERROR(IFERROR(IFERROR(IFERROR(IFERROR(INDEX(日常水質!$J$22:$N$22,MATCH($A10,日常水質!$J$14:$N$14,0)),INDEX(日常水質!$J$68:$N$68,MATCH($A10,日常水質!$J$60:$N$60,0))),INDEX(日常水質!$J$114:$N$114,MATCH($A10,日常水質!$J$106:$N$106,0))),INDEX(日常水質!$J$160:$N$160,MATCH($A10,日常水質!$J$152:$N$152,0))),INDEX(日常水質!$J$206:$N$206,MATCH($A10,日常水質!$J$198:$N$198,0))),"") | M10: =IFERROR(IFERROR(IFERROR(IFERROR(IFERROR(INDEX(日常水質!$J$23:$N$23,MATCH($A10,日常水質!$J$14:$N$14,0)),INDEX(日常水質!$J$69:$N$69,MATCH($A10,日常水質!$J$60:$N$60,0))),INDEX(日常水質!$J$115:$N$115,MATCH($A10,日常水質!$J$106:$N$106,0))),INDEX(日常水質!$J$161:$N$161,MATCH($A10,日常水質!$J$152:$N$152,0))),INDEX(日常水質!$J$207:$N$207,MATCH($A10,日常水質!$J$198:$N$198,0))),"") | O10: =IFERROR(IFERROR(IFERROR(IFERROR(IFERROR(INDEX(日常水質!$J$34:$N$34,MATCH($A10,日常水質!$J$14:$N$14,0)),INDEX(日常水質!$J$80:$N$80,MATCH($A10,日常水質!$J$60:$N$60,0))),INDEX(日常水質!$J$126:$N$126,MATCH($A10,日常水質!$J$106:$N$106,0))),INDEX(日常水質!$J$172:$N$172,MATCH($A10,日常水質!$J$152:$N$152,0))),INDEX(日常水質!$J$218:$N$218,MATCH($A10,日常水質!$J$198:$N$198,0))),"") | P10: =IFERROR(IFERROR(IFERROR(IFERROR(IFERROR(INDEX(日常水質!$J$32:$N$32,MATCH($A10,日常水質!$J$14:$N$14,0)),INDEX(日常水質!$J$78:$N$78,MATCH($A10,日常水質!$J$60:$N$60,0))),INDEX(日常水質!$J$124:$N$124,MATCH($A10,日常水質!$J$106:$N$106,0))),INDEX(日常水質!$J$170:$N$170,MATCH($A10,日常水質!$J$152:$N$152,0))),INDEX(日常水質!$J$216:$N$216,MATCH($A10,日常水質!$J$198:$N$198,0))),"") | Q10: =IFERROR(IFERROR(IFERROR(IFERROR(IFERROR(INDEX(日常水質!$J$36:$N$36,MATCH($A10,日常水質!$J$14:$N$14,0)),INDEX(日常水質!$J$82:$N$82,MATCH($A10,日常水質!$J$60:$N$60,0))),INDEX(日常水質!$J$128:$N$128,MATCH($A10,日常水質!$J$106:$N$106,0))),INDEX(日常水質!$J$174:$N$174,MATCH($A10,日常水質!$J$152:$N$152,0))),INDEX(日常水質!$J$220:$N$220,MATCH($A10,日常水質!$J$198:$N$198,0))),"")
A11: =IF(ISNUMBER(A10),IF(MONTH(A10+1)=MONTH($A$8),A10+1,""),"") | B11: =IF(ISNUMBER(A11),A11,"") | C11: =IFERROR(IFERROR(IFERROR(IFERROR(IFERROR(INDEX(日常水質!$J$16:$N$16,MATCH($A11,日常水質!$J$14:$N$14,0)),INDEX(日常水質!$J$62:$N$62,MATCH($A11,日常水質!$J$60:$N$60,0))),INDEX(日常水質!$J$108:$N$108,MATCH($A11,日常水質!$J$106:$N$106,0))),INDEX(日常水質!$J$154:$N$154,MATCH($A11,日常水質!$J$152:$N$152,0))),INDEX(日常水質!$J$200:$N$200,MATCH($A11,日常水質!$J$198:$N$198,0))),"") | D11: =IFERROR(IFERROR(IFERROR(IFERROR(IFERROR(INDEX(日常水質!$J$17:$N$17,MATCH($A11,日常水質!$J$14:$N$14,0)),INDEX(日常水質!$J$63:$N$63,MATCH($A11,日常水質!$J$60:$N$60,0))),INDEX(日常水質!$J$109:$N$109,MATCH($A11,日常水質!$J$106:$N$106,0))),INDEX(日常水質!$J$155:$N$155,MATCH($A11,日常水質!$J$152:$N$152,0))),INDEX(日常水質!$J$201:$N$201,MATCH($A11,日常水質!$J$198:$N$198,0))),"") | F11: =IFERROR(IFERROR(IFERROR(IFERROR(IFERROR(INDEX(日常水質!$J$18:$N$18,MATCH($A11,日常水質!$J$14:$N$14,0)),INDEX(日常水質!$J$64:$N$64,MATCH($A11,日常水質!$J$60:$N$60,0))),INDEX(日常水質!$J$110:$N$110,MATCH($A11,日常水質!$J$106:$N$106,0))),INDEX(日常水質!$J$156:$N$156,MATCH($A11,日常水質!$J$152:$N$152,0))),INDEX(日常水質!$J$202:$N$202,MATCH($A11,日常水質!$J$198:$N$198,0))),"") | G11: =IFERROR(IFERROR(IFERROR(IFERROR(IFERROR(INDEX(日常水質!$J$27:$N$27,MATCH($A11,日常水質!$J$14:$N$14,0)),INDEX(日常水質!$J$73:$N$73,MATCH($A11,日常水質!$J$60:$N$60,0))),INDEX(日常水質!$J$119:$N$119,MATCH($A11,日常水質!$J$106:$N$106,0))),INDEX(日常水質!$J$165:$N$165,MATCH($A11,日常水質!$J$152:$N$152,0))),INDEX(日常水質!$J$211:$N$211,MATCH($A11,日常水質!$J$198:$N$198,0))),"") | H11: =IFERROR(IFERROR(IFERROR(IFERROR(IFERROR(INDEX(日常水質!$J$28:$N$28,MATCH($A11,日常水質!$J$14:$N$14,0)),INDEX(日常水質!$J$74:$N$74,MATCH($A11,日常水質!$J$60:$N$60,0))),INDEX(日常水質!$J$120:$N$120,MATCH($A11,日常水質!$J$106:$N$106,0))),INDEX(日常水質!$J$166:$N$166,MATCH($A11,日常水質!$J$152:$N$152,0))),INDEX(日常水質!$J$212:$N$212,MATCH($A11,日常水質!$J$198:$N$198,0))),"") | J11: =IFERROR(IFERROR(IFERROR(IFERROR(IFERROR(INDEX(日常水質!$J$29:$N$29,MATCH($A11,日常水質!$J$14:$N$14,0)),INDEX(日常水質!$J$75:$N$75,MATCH($A11,日常水質!$J$60:$N$60,0))),INDEX(日常水質!$J$121:$N$121,MATCH($A11,日常水質!$J$106:$N$106,0))),INDEX(日常水質!$J$167:$N$167,MATCH($A11,日常水質!$J$152:$N$152,0))),INDEX(日常水質!$J$213:$N$213,MATCH($A11,日常水質!$J$198:$N$198,0))),"") | K11: =IFERROR(IFERROR(IFERROR(IFERROR(IFERROR(INDEX(日常水質!$J$22:$N$22,MATCH($A11,日常水質!$J$14:$N$14,0)),INDEX(日常水質!$J$68:$N$68,MATCH($A11,日常水質!$J$60:$N$60,0))),INDEX(日常水質!$J$114:$N$114,MATCH($A11,日常水質!$J$106:$N$106,0))),INDEX(日常水質!$J$160:$N$160,MATCH($A11,日常水質!$J$152:$N$152,0))),INDEX(日常水質!$J$206:$N$206,MATCH($A11,日常水質!$J$198:$N$198,0))),"") | M11: =IFERROR(IFERROR(IFERROR(IFERROR(IFERROR(INDEX(日常水質!$J$23:$N$23,MATCH($A11,日常水質!$J$14:$N$14,0)),INDEX(日常水質!$J$69:$N$69,MATCH($A11,日常水質!$J$60:$N$60,0))),INDEX(日常水質!$J$115:$N$115,MATCH($A11,日常水質!$J$106:$N$106,0))),INDEX(日常水質!$J$161:$N$161,MATCH($A11,日常水質!$J$152:$N$152,0))),INDEX(日常水質!$J$207:$N$207,MATCH($A11,日常水質!$J$198:$N$198,0))),"") | O11: =IFERROR(IFERROR(IFERROR(IFERROR(IFERROR(INDEX(日常水質!$J$34:$N$34,MATCH($A11,日常水質!$J$14:$N$14,0)),INDEX(日常水質!$J$80:$N$80,MATCH($A11,日常水質!$J$60:$N$60,0))),INDEX(日常水質!$J$126:$N$126,MATCH($A11,日常水質!$J$106:$N$106,0))),INDEX(日常水質!$J$172:$N$172,MATCH($A11,日常水質!$J$152:$N$152,0))),INDEX(日常水質!$J$218:$N$218,MATCH($A11,日常水質!$J$198:$N$198,0))),"") | P11: =IFERROR(IFERROR(IFERROR(IFERROR(IFERROR(INDEX(日常水質!$J$32:$N$32,MATCH($A11,日常水質!$J$14:$N$14,0)),INDEX(日常水質!$J$78:$N$78,MATCH($A11,日常水質!$J$60:$N$60,0))),INDEX(日常水質!$J$124:$N$124,MATCH($A11,日常水質!$J$106:$N$106,0))),INDEX(日常水質!$J$170:$N$170,MATCH($A11,日常水質!$J$152:$N$152,0))),INDEX(日常水質!$J$216:$N$216,MATCH($A11,日常水質!$J$198:$N$198,0))),"") | Q11: =IFERROR(IFERROR(IFERROR(IFERROR(IFERROR(INDEX(日常水質!$J$36:$N$36,MATCH($A11,日常水質!$J$14:$N$14,0)),INDEX(日常水質!$J$82:$N$82,MATCH($A11,日常水質!$J$60:$N$60,0))),INDEX(日常水質!$J$128:$N$128,MATCH($A11,日常水質!$J$106:$N$106,0))),INDEX(日常水質!$J$174:$N$174,MATCH($A11,日常水質!$J$152:$N$152,0))),INDEX(日常水質!$J$220:$N$220,MATCH($A11,日常水質!$J$198:$N$198,0))),"")
A12: =IF(ISNUMBER(A11),IF(MONTH(A11+1)=MONTH($A$8),A11+1,""),"") | B12: =IF(ISNUMBER(A12),A12,"") | C12: =IFERROR(IFERROR(IFERROR(IFERROR(IFERROR(INDEX(日常水質!$J$16:$N$16,MATCH($A12,日常水質!$J$14:$N$14,0)),INDEX(日常水質!$J$62:$N$62,MATCH($A12,日常水質!$J$60:$N$60,0))),INDEX(日常水質!$J$108:$N$108,MATCH($A12,日常水質!$J$106:$N$106,0))),INDEX(日常水質!$J$154:$N$154,MATCH($A12,日常水質!$J$152:$N$152,0))),INDEX(日常水質!$J$200:$N$200,MATCH($A12,日常水質!$J$198:$N$198,0))),"") | D12: =IFERROR(IFERROR(IFERROR(IFERROR(IFERROR(INDEX(日常水質!$J$17:$N$17,MATCH($A12,日常水質!$J$14:$N$14,0)),INDEX(日常水質!$J$63:$N$63,MATCH($A12,日常水質!$J$60:$N$60,0))),INDEX(日常水質!$J$109:$N$109,MATCH($A12,日常水質!$J$106:$N$106,0))),INDEX(日常水質!$J$155:$N$155,MATCH($A12,日常水質!$J$152:$N$152,0))),INDEX(日常水質!$J$201:$N$201,MATCH($A12,日常水質!$J$198:$N$198,0))),"") | F12: =IFERROR(IFERROR(IFERROR(IFERROR(IFERROR(INDEX(日常水質!$J$18:$N$18,MATCH($A12,日常水質!$J$14:$N$14,0)),INDEX(日常水質!$J$64:$N$64,MATCH($A12,日常水質!$J$60:$N$60,0))),INDEX(日常水質!$J$110:$N$110,MATCH($A12,日常水質!$J$106:$N$106,0))),INDEX(日常水質!$J$156:$N$156,MATCH($A12,日常水質!$J$152:$N$152,0))),INDEX(日常水質!$J$202:$N$202,MATCH($A12,日常水質!$J$198:$N$198,0))),"") | G12: =IFERROR(IFERROR(IFERROR(IFERROR(IFERROR(INDEX(日常水質!$J$27:$N$27,MATCH($A12,日常水質!$J$14:$N$14,0)),INDEX(日常水質!$J$73:$N$73,MATCH($A12,日常水質!$J$60:$N$60,0))),INDEX(日常水質!$J$119:$N$119,MATCH($A12,日常水質!$J$106:$N$106,0))),INDEX(日常水質!$J$165:$N$165,MATCH($A12,日常水質!$J$152:$N$152,0))),INDEX(日常水質!$J$211:$N$211,MATCH($A12,日常水質!$J$198:$N$198,0))),"") | H12: =IFERROR(IFERROR(IFERROR(IFERROR(IFERROR(INDEX(日常水質!$J$28:$N$28,MATCH($A12,日常水質!$J$14:$N$14,0)),INDEX(日常水質!$J$74:$N$74,MATCH($A12,日常水質!$J$60:$N$60,0))),INDEX(日常水質!$J$120:$N$120,MATCH($A12,日常水質!$J$106:$N$106,0))),INDEX(日常水質!$J$166:$N$166,MATCH($A12,日常水質!$J$152:$N$152,0))),INDEX(日常水質!$J$212:$N$212,MATCH($A12,日常水質!$J$198:$N$198,0))),"") | J12: =IFERROR(IFERROR(IFERROR(IFERROR(IFERROR(INDEX(日常水質!$J$29:$N$29,MATCH($A12,日常水質!$J$14:$N$14,0)),INDEX(日常水質!$J$75:$N$75,MATCH($A12,日常水質!$J$60:$N$60,0))),INDEX(日常水質!$J$121:$N$121,MATCH($A12,日常水質!$J$106:$N$106,0))),INDEX(日常水質!$J$167:$N$167,MATCH($A12,日常水質!$J$152:$N$152,0))),INDEX(日常水質!$J$213:$N$213,MATCH($A12,日常水質!$J$198:$N$198,0))),"") | K12: =IFERROR(IFERROR(IFERROR(IFERROR(IFERROR(INDEX(日常水質!$J$22:$N$22,MATCH($A12,日常水質!$J$14:$N$14,0)),INDEX(日常水質!$J$68:$N$68,MATCH($A12,日常水質!$J$60:$N$60,0))),INDEX(日常水質!$J$114:$N$114,MATCH($A12,日常水質!$J$106:$N$106,0))),INDEX(日常水質!$J$160:$N$160,MATCH($A12,日常水質!$J$152:$N$152,0))),INDEX(日常水質!$J$206:$N$206,MATCH($A12,日常水質!$J$198:$N$198,0))),"") | M12: =IFERROR(IFERROR(IFERROR(IFERROR(IFERROR(INDEX(日常水質!$J$23:$N$23,MATCH($A12,日常水質!$J$14:$N$14,0)),INDEX(日常水質!$J$69:$N$69,MATCH($A12,日常水質!$J$60:$N$60,0))),INDEX(日常水質!$J$115:$N$115,MATCH($A12,日常水質!$J$106:$N$106,0))),INDEX(日常水質!$J$161:$N$161,MATCH($A12,日常水質!$J$152:$N$152,0))),INDEX(日常水質!$J$207:$N$207,MATCH($A12,日常水質!$J$198:$N$198,0))),"") | O12: =IFERROR(IFERROR(IFERROR(IFERROR(IFERROR(INDEX(日常水質!$J$34:$N$34,MATCH($A12,日常水質!$J$14:$N$14,0)),INDEX(日常水質!$J$80:$N$80,MATCH($A12,日常水質!$J$60:$N$60,0))),INDEX(日常水質!$J$126:$N$126,MATCH($A12,日常水質!$J$106:$N$106,0))),INDEX(日常水質!$J$172:$N$172,MATCH($A12,日常水質!$J$152:$N$152,0))),INDEX(日常水質!$J$218:$N$218,MATCH($A12,日常水質!$J$198:$N$198,0))),"") | P12: =IFERROR(IFERROR(IFERROR(IFERROR(IFERROR(INDEX(日常水質!$J$32:$N$32,MATCH($A12,日常水質!$J$14:$N$14,0)),INDEX(日常水質!$J$78:$N$78,MATCH($A12,日常水質!$J$60:$N$60,0))),INDEX(日常水質!$J$124:$N$124,MATCH($A12,日常水質!$J$106:$N$106,0))),INDEX(日常水質!$J$170:$N$170,MATCH($A12,日常水質!$J$152:$N$152,0))),INDEX(日常水質!$J$216:$N$216,MATCH($A12,日常水質!$J$198:$N$198,0))),"") | Q12: =IFERROR(IFERROR(IFERROR(IFERROR(IFERROR(INDEX(日常水質!$J$36:$N$36,MATCH($A12,日常水質!$J$14:$N$14,0)),INDEX(日常水質!$J$82:$N$82,MATCH($A12,日常水質!$J$60:$N$60,0))),INDEX(日常水質!$J$128:$N$128,MATCH($A12,日常水質!$J$106:$N$106,0))),INDEX(日常水質!$J$174:$N$174,MATCH($A12,日常水質!$J$152:$N$152,0))),INDEX(日常水質!$J$220:$N$220,MATCH($A12,日常水質!$J$198:$N$198,0))),"")
